Workbook

Sheet Data Input
C1: Tỷ giá | D1: 23300 | E1: Lãi suất NH% | F1: 7.5 | G1: CPQL% | H1: 3 | I1: GENERAL INFORMATION | AB1: BUYING RATE | BR1: SELLING RATE | DT1: VAT (%) | EB1: GVDV | EC1: DTLH | ED1: CKTM (COM) after Tax | EF1: CPCN 0% | EH1: CPCN LCC 8% | EJ1: CPCN CUS+TRUCKING | EL1: CP KHÁC | EO1: CP THU HỘ | EQ1: KQKD | ER1: TỶ GIÁ | ES1: INTEREST %
A2: NO. | B2: DEP. | C2: KEYS | D2: SHPR | E2: CNEE | F2: AGENT | G2: POL | H2: POD | I2: PICK UP | J2: DELIVERY | K2: 20' | L2: 40' | M2: LCL | N2: WEIGHT | O2: SALES | P2: ATTN | Q2: EXECUTOR | R2: LINE/CO-LOADER | S2: LINE | T2: TIME of BOOKING | U2: ETD | V2: ETA | W2: ATD | X2: ATA | Y2: T/T | Z2: TERM | AA2: V.V | AB2: 20' | AP2: 40' | BD2: LCL/AIR | BR2: 20' | CJ2: 40' | DB2: LCL/AIR | DT2: COST | DX2: REVENUE
AB3: OVERSEAS | AD3: O/F | AE3: DO/BILL | AF3: THC | AG3: CFS | AH3: CIC | AI3: HDL/TLX BILL/LATE PAYMENT | AJ3: CLEAN | AK3: OTHER | AL3: TRUCK | AM3: CUS | AN3: COM LINE | AP3: OVERSEAS | AR3: O/F | AS3: DO/BILL | AT3: THC | AU3: CFS | AV3: CIC | AW3: HDL/TLX BILL/LATE PAYMENT | AX3: CLEAN | AY3: OTHER | AZ3: TRUCK | BA3: CUS | BB3: COM LINE | BD3: OVERSEAS | BF3: O/F | BG3: DO/BILL | BH3: THC | BI3: CFS | BJ3: CIC | BK3: HDL/TLX BILL/LATE PAYMENT | BL3: CLEAN | BM3: OTHER | BN3: TRUCK | BO3: CUS | BP3: COM LINE | BR3: OVERSEAS | BT3: O/F | BU3: DO/BILL | BV3: THC | BW3: CFS | BX3: CIC | BY3: HDL/TLX BILL/LATE PAYMENT | BZ3: CLEAN | CA3: OTHER | CB3: TRUCK | CC3: CUS | CD3: COM | CG3: COM 10% | CJ3: OVERSEAS | CL3: O/F | CM3: DO/BILL | CN3: THC | CO3: CFS | CP3: CIC | CQ3: HDL/TLX BILL/LATE PAYMENT | CR3: CLEAN | CS3: OTHER | CT3: TRUCK | CU3: CUS | CV3: COM | CY3: COM 10% | DB3: OVERSEAS | DD3: O/F | DE3: DO/BILL | DF3: THC | DG3: CFS | DH3: CIC | DI3: HDL/TLX BILL/LATE PAYMENT | DJ3: CLEAN | DK3: OTHER | DL3: TRUCK | DM3: CUS | DN3: COM | DQ3: COM 10% | DT3: 1 | DU3: 2 | DV3: 3 | DW3: 4 | DX3: 1 | DY3: 2 | DZ3: 3 | EA3: 4 | ED3: LINE | EE3: CLIENT | EF3: Credit (day) | EG3: Interest | EH3: Credit (day) | EI3: Interest | EJ3: Credit (day) | EK3: Interest | EM3: CƯỢC CONT | EN3: Credit (day) | EO3: CHI HỘ KHÁC | EP3: Credit (day)
AB4: /SHPT | AC4: /20' | AN4: Amount | AO4: Tax % | AP4: /SHPT | AQ4: /40' | BB4: Amount | BC4: Tax | BD4: /SHPT | BE4: /CBM | BP4: Amount | BQ4: Tax | BR4: /SHPT | BS4: /20' | CD4: /SHPT | CE4: /CONT | CF4: Tax % | CG4: /SHPT | CH4: /CONT | CI4: Tax % | CJ4: /SHPT | CK4: /40' | CV4: /SHPT | CW4: /CONT | CX4: Tax % | CY4: /SHPT | CZ4: /CONT | DA4: Tax % | DB4: /SHPT | DC4: /CBM | DN4: /SHPT | DO4: /CBM | DP4: Tax % | DQ4: /SHPT | DR4: /CBM | DS4: Tax % | DT4: OVS | DU4: O/F | DV4: LCC | DW4: CUS+TRUCK | DX4: OVS | DY4: O/F | DZ4: LCC | EA4: CUS+TRUCK | EM4: /SHPT | EO4: /SHPT
A5: 1 | C5: 2 | D5: 3 | E5: 4 | F5: 5 | G5: 6 | H5: 7 | I5: 8 | J5: 9 | K5: 10 | L5: 11 | M5: 12 | N5: 13 | O5: 14 | P5: 15 | Q5: 16 | R5: 17 | S5: 18 | T5: 19 | U5: 20 | V5: 21 | W5: 22 | X5: 23 | Y5: 24 | Z5: 25 | AA5: 26 | AB5: 27 | AC5: 28 | AD5: 29 | AE5: 30 | AF5: 31 | AG5: 32 | AH5: 33 | AI5: 34 | AJ5: 35 | AK5: 36 | AL5: 37 | AM5: 38 | AN5: 39 | AO5: 40 | AP5: 41 | AQ5: 42 | AR5: 43 | AS5: 44 | AT5: 45 | AU5: 46 | AV5: 47 | AW5: 48 | AX5: 49 | AY5: 50 | AZ5: 51 | BA5: 52 | BB5: 53 | BC5: 54 | BD5: 55 | BE5: 56 | BF5: 57 | BG5: 58 | BH5: 59 | BI5: 60 | BJ5: 61 | BK5: 62 | BL5: 63 | BM5: 64 | BN5: 65 | BO5: 66 | BP5: 67 | BQ5: 68 | BR5: 69 | BS5: 70 | BT5: 71 | BU5: 72 | BV5: 73 | BW5: 74 | BX5: 75 | BY5: 76 | BZ5: 77 | CA5: 78 | CB5: 79 | CC5: 80 | CD5: 81 | CE5: 82 | CF5: 83 | CG5: 84 | CH5: 85 | CI5: 86 | CJ5: 87 | CK5: 88 | CL5: 89 | CM5: 90 | CN5: 91 | CO5: 92 | CP5: 93 | CQ5: 94 | CR5: 95 | CS5: 96 | CT5: 97 | CU5: 98 | CV5: 99 | CW5: 100 | CX5: 101 | CY5: 102 | CZ5: 103 | DA5: 104 | DB5: 105 | DC5: 106 | DD5: 107 | DE5: 108 | DF5: 109 | DG5: 110 | DH5: 111 | DI5: 112 | DJ5: 113 | DK5: 114 | DL5: 115 | DM5: 116 | DN5: 117 | DO5: 118 | DP5: 119 | DQ5: 120 | DR5: 121 | DS5: 122 | DT5: 123 | DU5: 124 | DV5: 125 | DW5: 126 | DX5: 127 | DY5: 128 | DZ5: 129 | EA5: 130 | EB5: 131 | EC5: 132 | ED5: 133 | EE5: 134 | EF5: 135 | EG5: 136 | EH5: 137 | EI5: 138 | EJ5: 139 | EK5: 140 | EL5: 141 | EM5: 142 | EN5: 143 | EO5: 144 | EP5: 145 | EQ5: 146 | ER5: 147 | ES5: 148
A6: 1 | B6: SAL | C6: ASW-VN000001 | D6: TAM LAP THANH | E6: NEOPRENE SOLUTIONS | F6: COTRANSA | G6: HOCHIMINH | H6: BILBAO | I6: HOCHIMINH | J6: SPAIN | K6: 1 | O6: TIN HO | R6: SITC | U6: 46173 | V6: 46234 | AE6: 32.62 | AF6: 103.15 | AK6: 38.22 | AN6: 20 | BU6: 50.09 | BV6: 135.23 | BY6: 58 | CA6: 50.09 | CE6: 20 | DN6: 30 | DP6: 10 | EB6: =AB6+AC6*K6+AD6*K6+((AF6+AG6+AH6+AJ6+AK6)*K6+AE6+AI6+AL6*K6+AM6*K6)+AP6+AQ6*L6+AR6*L6+((AT6+AU6+AV6+AX6+AY6)*L6+AS6+AW6+AZ6*L6+BA6*L6)+IF(AND(M6>0,MAX(M6,N6/1000)<1),BD6+1*(BE6+BF6)+(1*(BH6+BI6+BJ6+BL6+BM6)+BG6+BK6+BN6+BO6),IF(AND(M6>0,MAX(M6,N6/1000)>1),BD6+MAX(M6,N6/1000)*(BE6+BF6)+(MAX(M6,N6/1000)*(BH6+BI6+BJ6+BL6+BM6)+BG6+BK6+BN6+BO6),IF(AND(K6="",L6="",M6=""),BD6+N6*(BE6+BF6)+((BH6+BI6+BJ6+BL6+BM6)*N6+BG6+BK6+BN6+BO6),0))) -> 173.99 | EC6: =BR6+BS6*K6+BT6*K6+((BV6+BW6+BX6+BZ6+CA6)*K6+BU6+BY6+CB6*K6+CC6*K6)+CJ6+CK6*L6+CL6*L6+((CN6+CO6+CP6+CR6+CS6)*L6+CM6+CQ6+CT6*L6+CU6*L6)+IF(AND(M6>0,MAX(M6,N6/1000)<1),DB6+1*(DC6+DD6)+(1*(DF6+DG6+DH6+DJ6+DK6)+DE6+DI6+DL6+DM6),IF(AND(M6>0,MAX(M6,N6/1000)>1),DB6+MAX(M6,N6/1000)*(DC6+DD6)+(MAX(M6,N6/1000)*(DF6+DG6+DH6+DJ6+DK6)+DE6+DI6+DL6+DM6),IF(AND(K6="",L6="",M6=""),DB6+N6*(DC6+DD6)+((DF6+DG6+DH6+DJ6+DK6)*N6+DE6+DI6+DL6+DM6),0))) -> 293.41 | ED6: =AN6*K6*(1-AO6%)+BB6*L6*(1-BC6%)+BP6*IF(AND(M6>0,M6<1),1,IF(M6>1,MAX(M6,N6/1000),N6))*(1-BQ6%) -> 20 | EE6: =(CD6+CE6*K6)*(1-CF6%)+(CG6+CH6*K6)*(1-CI6%)+(CV6+CW6*L6)*(1-CX6%)+(CY6+CZ6*L6)*(1-DA6%)+(DN6+DO6*IF(AND(M6>0,M6<1),1,IF(M6>1,MAX(M6,N6/1000),N6)))*(1-DP6%)+(DQ6+DR6*IF(AND(M6>0,M6<1),1,IF(M6>1,MAX(M6,N6/1000),N6)))*(1-DS6%) -> 47 | EG6: =((BR6+BS6*K6+BT6*K6)+(CJ6+CK6*L6*+CL6*L6)+IF(AND(M6>0,MAX(M6,N6/1000)<1),DB6+DC6+DD6,IF(AND(M6>0,MAX(M6,N6/1000)>1),DB6+DC6*M6+DD6*M6,IF(AND(M6>0,MAX(M6,N6/1000)>1),DB6+MAX(M6,N6/1000)*DC6+MAX(M6,N6/1000)*DD6+IF(AND(K6="",L6="",M6=""),DB6+DC6*N6+DD6*N6,0)))))*EF6/365*ES6% -> 0 | EI6: =(((BV6+BW6+BX6+BZ6+CA6)*K6+BU6+BY6)*1.08+CJ6+CK6*L6+CL6*L6+((CN6+CO6+CP6+CR6+CS6)*L6+CM6+CQ6)*1.08+IF(AND(M6>0,MAX(M6,N6/1000)<1),DB6+1*(DC6+DD6)+(1*(DF6+DG6+DH6+DJ6+DK6)+DE6+DI6)*1.08,IF(AND(M6>0,MAX(M6,N6/1000)>1),DB6+MAX(M6,N6/1000)*(DC6+DD6)+(MAX(M6,N6/1000)*(DF6+DG6+DH6+DJ6+DK6)+DE6+DI6)*1.08,IF(AND(K6="",L6="",M6=""),DB6+N6*(DC6+DD6)+((DF6+DG6+DH6+DJ6+DK6)*N6+DE6+DI6)*1.08,0))))*EH6/365*ES6% -> 0 | EK6: =((CB6*K6+CC6*K6)*1.1+(CT6*L6+CU6*L6)*1.1+(DL6+DM6)*1.1)*EJ6/365*ES6% -> 0 | EM6: 0 | EO6: 0 | EQ6: =EC6-EB6-EG6-EI6-EK6-(AN6*K6+BB6*L6+BP6*IF(AND(M6>0,M6<1),1,IF(M6>1,MAX(M6,N6/1000),N6))+CD6+CE6*K6+CV6+CW6*L6+DN6+DO6*IF(AND(M6>0,M6<1),1,IF(M6>1,MAX(M6,N6/1000),N6))+CG6+CH6*K6+CY6+CZ6*L6+DQ6+DR6*IF(AND(M6>0,M6<1),1,IF(M6>1,MAX(M6,N6/1000),N6)))-EL6-EM6*EN6/365*ES6%-EO6*EP6/365*ES6% -> 49.42 | ER6: 23300 | ES6: 7.5
A7: 2 | B7: SAL | C7: ASW-VN000002 | D7: ACCREDO ASIA | E7: ACCREDO PACKAGING INC. | F7: ROYAL CARGO INC USA | G7: HOCHIMINH | H7: HOUSTON | I7: HOCHIMINH | J7: USA | L7: 5 | U7: 46147 | V7: 46184 | AR7: 13774.72 | AS7: 49.55 | AT7: 188.29 | AW7: 34.68 | AY7: 49.55 | CL7: 14666.609 | CM7: 39.639485 | CN7: 183.33262 | CQ7: 34.684549 | CS7: 44.594421 | CW7: 260.60086 | CX7: 20 | DV7: 8 | DZ7: 8 | EB7: =AB7+AC7*K7+AD7*K7+((AF7+AG7+AH7+AJ7+AK7)*K7+AE7+AI7+AL7*K7+AM7*K7)+AP7+AQ7*L7+AR7*L7+((AT7+AU7+AV7+AX7+AY7)*L7+AS7+AW7+AZ7*L7+BA7*L7)+IF(AND(M7>0,MAX(M7,N7/1000)<1),BD7+1*(BE7+BF7)+(1*(BH7+BI7+BJ7+BL7+BM7)+BG7+BK7+BN7+BO7),IF(AND(M7>0,MAX(M7,N7/1000)>1),BD7+MAX(M7,N7/1000)*(BE7+BF7)+(MAX(M7,N7/1000)*(BH7+BI7+BJ7+BL7+BM7)+BG7+BK7+BN7+BO7),IF(AND(K7="",L7="",M7=""),BD7+N7*(BE7+BF7)+((BH7+BI7+BJ7+BL7+BM7)*N7+BG7+BK7+BN7+BO7),0))) -> 70147.03 | EC7: =BR7+BS7*K7+BT7*K7+((BV7+BW7+BX7+BZ7+CA7)*K7+BU7+BY7+CB7*K7+CC7*K7)+CJ7+CK7*L7+CL7*L7+((CN7+CO7+CP7+CR7+CS7)*L7+CM7+CQ7+CT7*L7+CU7*L7)+IF(AND(M7>0,MAX(M7,N7/1000)<1),DB7+1*(DC7+DD7)+(1*(DF7+DG7+DH7+DJ7+DK7)+DE7+DI7+DL7+DM7),IF(AND(M7>0,MAX(M7,N7/1000)>1),DB7+MAX(M7,N7/1000)*(DC7+DD7)+(MAX(M7,N7/1000)*(DF7+DG7+DH7+DJ7+DK7)+DE7+DI7+DL7+DM7),IF(AND(K7="",L7="",M7=""),DB7+N7*(DC7+DD7)+((DF7+DG7+DH7+DJ7+DK7)*N7+DE7+DI7+DL7+DM7),0))) -> 74547.006 | ED7: =AN7*K7*(1-AO7%)+BB7*L7*(1-BC7%)+BP7*IF(AND(M7>0,M7<1),1,IF(M7>1,MAX(M7,N7/1000),N7))*(1-BQ7%) -> 0 | EE7: =(CD7+CE7*K7)*(1-CF7%)+(CG7+CH7*K7)*(1-CI7%)+(CV7+CW7*L7)*(1-CX7%)+(CY7+CZ7*L7)*(1-DA7%)+(DN7+DO7*IF(AND(M7>0,M7<1),1,IF(M7>1,MAX(M7,N7/1000),N7)))*(1-DP7%)+(DQ7+DR7*IF(AND(M7>0,M7<1),1,IF(M7>1,MAX(M7,N7/1000),N7)))*(1-DS7%) -> 1042.4034 | EG7: =((BR7+BS7*K7+BT7*K7)+(CJ7+CK7*L7*+CL7*L7)+IF(AND(M7>0,MAX(M7,N7/1000)<1),DB7+DC7+DD7,IF(AND(M7>0,MAX(M7,N7/1000)>1),DB7+DC7*M7+DD7*M7,IF(AND(M7>0,MAX(M7,N7/1000)>1),DB7+MAX(M7,N7/1000)*DC7+MAX(M7,N7/1000)*DD7+IF(AND(K7="",L7="",M7=""),DB7+DC7*N7+DD7*N7,0)))))*EF7/365*ES7% -> 0 | EI7: =(((BV7+BW7+BX7+BZ7+CA7)*K7+BU7+BY7)*1.08+CJ7+CK7*L7+CL7*L7+((CN7+CO7+CP7+CR7+CS7)*L7+CM7+CQ7)*1.08+IF(AND(M7>0,MAX(M7,N7/1000)<1),DB7+1*(DC7+DD7)+(1*(DF7+DG7+DH7+DJ7+DK7)+DE7+DI7)*1.08,IF(AND(M7>0,MAX(M7,N7/1000)>1),DB7+MAX(M7,N7/1000)*(DC7+DD7)+(MAX(M7,N7/1000)*(DF7+DG7+DH7+DJ7+DK7)+DE7+DI7)*1.08,IF(AND(K7="",L7="",M7=""),DB7+N7*(DC7+DD7)+((DF7+DG7+DH7+DJ7+DK7)*N7+DE7+DI7)*1.08,0))))*EH7/365*ES7% -> 0 | EK7: =((CB7*K7+CC7*K7)*1.1+(CT7*L7+CU7*L7)*1.1+(DL7+DM7)*1.1)*EJ7/365*ES7% -> 0 | EQ7: =EC7-EB7-EG7-EI7-EK7-(AN7*K7+BB7*L7+BP7*IF(AND(M7>0,M7<1),1,IF(M7>1,MAX(M7,N7/1000),N7))+CD7+CE7*K7+CV7+CW7*L7+DN7+DO7*IF(AND(M7>0,M7<1),1,IF(M7>1,MAX(M7,N7/1000),N7))+CG7+CH7*K7+CY7+CZ7*L7+DQ7+DR7*IF(AND(M7>0,M7<1),1,IF(M7>1,MAX(M7,N7/1000),N7)))-EL7-EM7*EN7/365*ES7%-EO7*EP7/365*ES7% -> 3096.9721 | ER7: 23300 | ES7: 7.5
A8: 3 | EB8: =AB8+AC8*K8+AD8*K8+((AF8+AG8+AH8+AJ8+AK8)*K8+AE8+AI8+AL8*K8+AM8*K8)+AP8+AQ8*L8+AR8*L8+((AT8+AU8+AV8+AX8+AY8)*L8+AS8+AW8+AZ8*L8+BA8*L8)+IF(AND(M8>0,MAX(M8,N8/1000)<1),BD8+1*(BE8+BF8)+(1*(BH8+BI8+BJ8+BL8+BM8)+BG8+BK8+BN8+BO8),IF(AND(M8>0,MAX(M8,N8/1000)>1),BD8+MAX(M8,N8/1000)*(BE8+BF8)+(MAX(M8,N8/1000)*(BH8+BI8+BJ8+BL8+BM8)+BG8+BK8+BN8+BO8),IF(AND(K8="",L8="",M8=""),BD8+N8*(BE8+BF8)+((BH8+BI8+BJ8+BL8+BM8)*N8+BG8+BK8+BN8+BO8),0))) -> 0 | EC8: =BR8+BS8*K8+BT8*K8+((BV8+BW8+BX8+BZ8+CA8)*K8+BU8+BY8+CB8*K8+CC8*K8)+CJ8+CK8*L8+CL8*L8+((CN8+CO8+CP8+CR8+CS8)*L8+CM8+CQ8+CT8*L8+CU8*L8)+IF(AND(M8>0,MAX(M8,N8/1000)<1),DB8+1*(DC8+DD8)+(1*(DF8+DG8+DH8+DJ8+DK8)+DE8+DI8+DL8+DM8),IF(AND(M8>0,MAX(M8,N8/1000)>1),DB8+MAX(M8,N8/1000)*(DC8+DD8)+(MAX(M8,N8/1000)*(DF8+DG8+DH8+DJ8+DK8)+DE8+DI8+DL8+DM8),IF(AND(K8="",L8="",M8=""),DB8+N8*(DC8+DD8)+((DF8+DG8+DH8+DJ8+DK8)*N8+DE8+DI8+DL8+DM8),0))) -> 0 | ED8: =AN8*K8*(1-AO8%)+BB8*L8*(1-BC8%)+BP8*IF(AND(M8>0,M8<1),1,IF(M8>1,MAX(M8,N8/1000),N8))*(1-BQ8%) -> 0 | EE8: =(CD8+CE8*K8)*(1-CF8%)+(CG8+CH8*K8)*(1-CI8%)+(CV8+CW8*L8)*(1-CX8%)+(CY8+CZ8*L8)*(1-DA8%)+(DN8+DO8*IF(AND(M8>0,M8<1),1,IF(M8>1,MAX(M8,N8/1000),N8)))*(1-DP8%)+(DQ8+DR8*IF(AND(M8>0,M8<1),1,IF(M8>1,MAX(M8,N8/1000),N8)))*(1-DS8%) -> 0 | EG8: =((BR8+BS8*K8+BT8*K8)+(CJ8+CK8*L8*+CL8*L8)+IF(AND(M8>0,MAX(M8,N8/1000)<1),DB8+DC8+DD8,IF(AND(M8>0,MAX(M8,N8/1000)>1),DB8+DC8*M8+DD8*M8,IF(AND(M8>0,MAX(M8,N8/1000)>1),DB8+MAX(M8,N8/1000)*DC8+MAX(M8,N8/1000)*DD8+IF(AND(K8="",L8="",M8=""),DB8+DC8*N8+DD8*N8,0)))))*EF8/365*ES8% -> 0 | EI8: =(((BV8+BW8+BX8+BZ8+CA8)*K8+BU8+BY8)*1.08+CJ8+CK8*L8+CL8*L8+((CN8+CO8+CP8+CR8+CS8)*L8+CM8+CQ8)*1.08+IF(AND(M8>0,MAX(M8,N8/1000)<1),DB8+1*(DC8+DD8)+(1*(DF8+DG8+DH8+DJ8+DK8)+DE8+DI8)*1.08,IF(AND(M8>0,MAX(M8,N8/1000)>1),DB8+MAX(M8,N8/1000)*(DC8+DD8)+(MAX(M8,N8/1000)*(DF8+DG8+DH8+DJ8+DK8)+DE8+DI8)*1.08,IF(AND(K8="",L8="",M8=""),DB8+N8*(DC8+DD8)+((DF8+DG8+DH8+DJ8+DK8)*N8+DE8+DI8)*1.08,0))))*EH8/365*ES8% -> 0 | EK8: =((CB8*K8+CC8*K8)*1.1+(CT8*L8+CU8*L8)*1.1+(DL8+DM8)*1.1)*EJ8/365*ES8% -> 0 | EQ8: =EC8-EB8-EG8-EI8-EK8-(AN8*K8+BB8*L8+BP8*IF(AND(M8>0,M8<1),1,IF(M8>1,MAX(M8,N8/1000),N8))+CD8+CE8*K8+CV8+CW8*L8+DN8+DO8*IF(AND(M8>0,M8<1),1,IF(M8>1,MAX(M8,N8/1000),N8))+CG8+CH8*K8+CY8+CZ8*L8+DQ8+DR8*IF(AND(M8>0,M8<1),1,IF(M8>1,MAX(M8,N8/1000),N8)))-EL8-EM8*EN8/365*ES8%-EO8*EP8/365*ES8% -> 0 | ER8: 23300 | ES8: 7.5
A9: 4 | EB9: =AB9+AC9*K9+AD9*K9+((AF9+AG9+AH9+AJ9+AK9)*K9+AE9+AI9+AL9*K9+AM9*K9)+AP9+AQ9*L9+AR9*L9+((AT9+AU9+AV9+AX9+AY9)*L9+AS9+AW9+AZ9*L9+BA9*L9)+IF(AND(M9>0,MAX(M9,N9/1000)<1),BD9+1*(BE9+BF9)+(1*(BH9+BI9+BJ9+BL9+BM9)+BG9+BK9+BN9+BO9),IF(AND(M9>0,MAX(M9,N9/1000)>1),BD9+MAX(M9,N9/1000)*(BE9+BF9)+(MAX(M9,N9/1000)*(BH9+BI9+BJ9+BL9+BM9)+BG9+BK9+BN9+BO9),IF(AND(K9="",L9="",M9=""),BD9+N9*(BE9+BF9)+((BH9+BI9+BJ9+BL9+BM9)*N9+BG9+BK9+BN9+BO9),0))) -> 0 | EC9: =BR9+BS9*K9+BT9*K9+((BV9+BW9+BX9+BZ9+CA9)*K9+BU9+BY9+CB9*K9+CC9*K9)+CJ9+CK9*L9+CL9*L9+((CN9+CO9+CP9+CR9+CS9)*L9+CM9+CQ9+CT9*L9+CU9*L9)+IF(AND(M9>0,MAX(M9,N9/1000)<1),DB9+1*(DC9+DD9)+(1*(DF9+DG9+DH9+DJ9+DK9)+DE9+DI9+DL9+DM9),IF(AND(M9>0,MAX(M9,N9/1000)>1),DB9+MAX(M9,N9/1000)*(DC9+DD9)+(MAX(M9,N9/1000)*(DF9+DG9+DH9+DJ9+DK9)+DE9+DI9+DL9+DM9),IF(AND(K9="",L9="",M9=""),DB9+N9*(DC9+DD9)+((DF9+DG9+DH9+DJ9+DK9)*N9+DE9+DI9+DL9+DM9),0))) -> 0 | ED9: =AN9*K9*(1-AO9%)+BB9*L9*(1-BC9%)+BP9*IF(AND(M9>0,M9<1),1,IF(M9>1,MAX(M9,N9/1000),N9))*(1-BQ9%) -> 0 | EE9: =(CD9+CE9*K9)*(1-CF9%)+(CG9+CH9*K9)*(1-CI9%)+(CV9+CW9*L9)*(1-CX9%)+(CY9+CZ9*L9)*(1-DA9%)+(DN9+DO9*IF(AND(M9>0,M9<1),1,IF(M9>1,MAX(M9,N9/1000),N9)))*(1-DP9%)+(DQ9+DR9*IF(AND(M9>0,M9<1),1,IF(M9>1,MAX(M9,N9/1000),N9)))*(1-DS9%) -> 0 | EG9: =((BR9+BS9*K9+BT9*K9)+(CJ9+CK9*L9*+CL9*L9)+IF(AND(M9>0,MAX(M9,N9/1000)<1),DB9+DC9+DD9,IF(AND(M9>0,MAX(M9,N9/1000)>1),DB9+DC9*M9+DD9*M9,IF(AND(M9>0,MAX(M9,N9/1000)>1),DB9+MAX(M9,N9/1000)*DC9+MAX(M9,N9/1000)*DD9+IF(AND(K9="",L9="",M9=""),DB9+DC9*N9+DD9*N9,0)))))*EF9/365*ES9% -> 0 | EI9: =(((BV9+BW9+BX9+BZ9+CA9)*K9+BU9+BY9)*1.08+CJ9+CK9*L9+CL9*L9+((CN9+CO9+CP9+CR9+CS9)*L9+CM9+CQ9)*1.08+IF(AND(M9>0,MAX(M9,N9/1000)<1),DB9+1*(DC9+DD9)+(1*(DF9+DG9+DH9+DJ9+DK9)+DE9+DI9)*1.08,IF(AND(M9>0,MAX(M9,N9/1000)>1),DB9+MAX(M9,N9/1000)*(DC9+DD9)+(MAX(M9,N9/1000)*(DF9+DG9+DH9+DJ9+DK9)+DE9+DI9)*1.08,IF(AND(K9="",L9="",M9=""),DB9+N9*(DC9+DD9)+((DF9+DG9+DH9+DJ9+DK9)*N9+DE9+DI9)*1.08,0))))*EH9/365*ES9% -> 0 | EK9: =((CB9*K9+CC9*K9)*1.1+(CT9*L9+CU9*L9)*1.1+(DL9+DM9)*1.1)*EJ9/365*ES9% -> 0 | EQ9: =EC9-EB9-EG9-EI9-EK9-(AN9*K9+BB9*L9+BP9*IF(AND(M9>0,M9<1),1,IF(M9>1,MAX(M9,N9/1000),N9))+CD9+CE9*K9+CV9+CW9*L9+DN9+DO9*IF(AND(M9>0,M9<1),1,IF(M9>1,MAX(M9,N9/1000),N9))+CG9+CH9*K9+CY9+CZ9*L9+DQ9+DR9*IF(AND(M9>0,M9<1),1,IF(M9>1,MAX(M9,N9/1000),N9)))-EL9-EM9*EN9/365*ES9%-EO9*EP9/365*ES9% -> 0 | ER9: 23300 | ES9: 7.5
A10: 5 | EB10: =AB10+AC10*K10+AD10*K10+((AF10+AG10+AH10+AJ10+AK10)*K10+AE10+AI10+AL10*K10+AM10*K10)+AP10+AQ10*L10+AR10*L10+((AT10+AU10+AV10+AX10+AY10)*L10+AS10+AW10+AZ10*L10+BA10*L10)+IF(AND(M10>0,MAX(M10,N10/1000)<1),BD10+1*(BE10+BF10)+(1*(BH10+BI10+BJ10+BL10+BM10)+BG10+BK10+BN10+BO10),IF(AND(M10>0,MAX(M10,N10/1000)>1),BD10+MAX(M10,N10/1000)*(BE10+BF10)+(MAX(M10,N10/1000)*(BH10+BI10+BJ10+BL10+BM10)+BG10+BK10+BN10+BO10),IF(AND(K10="",L10="",M10=""),BD10+N10*(BE10+BF10)+((BH10+BI10+BJ10+BL10+BM10)*N10+BG10+BK10+BN10+BO10),0))) -> 0 | EC10: =BR10+BS10*K10+BT10*K10+((BV10+BW10+BX10+BZ10+CA10)*K10+BU10+BY10+CB10*K10+CC10*K10)+CJ10+CK10*L10+CL10*L10+((CN10+CO10+CP10+CR10+CS10)*L10+CM10+CQ10+CT10*L10+CU10*L10)+IF(AND(M10>0,MAX(M10,N10/1000)<1),DB10+1*(DC10+DD10)+(1*(DF10+DG10+DH10+DJ10+DK10)+DE10+DI10+DL10+DM10),IF(AND(M10>0,MAX(M10,N10/1000)>1),DB10+MAX(M10,N10/1000)*(DC10+DD10)+(MAX(M10,N10/1000)*(DF10+DG10+DH10+DJ10+DK10)+DE10+DI10+DL10+DM10),IF(AND(K10="",L10="",M10=""),DB10+N10*(DC10+DD10)+((DF10+DG10+DH10+DJ10+DK10)*N10+DE10+DI10+DL10+DM10),0))) -> 0 | ED10: =AN10*K10*(1-AO10%)+BB10*L10*(1-BC10%)+BP10*IF(AND(M10>0,M10<1),1,IF(M10>1,MAX(M10,N10/1000),N10))*(1-BQ10%) -> 0 | EE10: =(CD10+CE10*K10)*(1-CF10%)+(CG10+CH10*K10)*(1-CI10%)+(CV10+CW10*L10)*(1-CX10%)+(CY10+CZ10*L10)*(1-DA10%)+(DN10+DO10*IF(AND(M10>0,M10<1),1,IF(M10>1,MAX(M10,N10/1000),N10)))*(1-DP10%)+(DQ10+DR10*IF(AND(M10>0,M10<1),1,IF(M10>1,MAX(M10,N10/1000),N10)))*(1-DS10%) -> 0 | EG10: =((BR10+BS10*K10+BT10*K10)+(CJ10+CK10*L10*+CL10*L10)+IF(AND(M10>0,MAX(M10,N10/1000)<1),DB10+DC10+DD10,IF(AND(M10>0,MAX(M10,N10/1000)>1),DB10+DC10*M10+DD10*M10,IF(AND(M10>0,MAX(M10,N10/1000)>1),DB10+MAX(M10,N10/1000)*DC10+MAX(M10,N10/1000)*DD10+IF(AND(K10="",L10="",M10=""),DB10+DC10*N10+DD10*N10,0)))))*EF10/365*ES10% -> 0 | EI10: =(((BV10+BW10+BX10+BZ10+CA10)*K10+BU10+BY10)*1.08+CJ10+CK10*L10+CL10*L10+((CN10+CO10+CP10+CR10+CS10)*L10+CM10+CQ10)*1.08+IF(AND(M10>0,MAX(M10,N10/1000)<1),DB10+1*(DC10+DD10)+(1*(DF10+DG10+DH10+DJ10+DK10)+DE10+DI10)*1.08,IF(AND(M10>0,MAX(M10,N10/1000)>1),DB10+MAX(M10,N10/1000)*(DC10+DD10)+(MAX(M10,N10/1000)*(DF10+DG10+DH10+DJ10+DK10)+DE10+DI10)*1.08,IF(AND(K10="",L10="",M10=""),DB10+N10*(DC10+DD10)+((DF10+DG10+DH10+DJ10+DK10)*N10+DE10+DI10)*1.08,0))))*EH10/365*ES10% -> 0 | EK10: =((CB10*K10+CC10*K10)*1.1+(CT10*L10+CU10*L10)*1.1+(DL10+DM10)*1.1)*EJ10/365*ES10% -> 0 | EQ10: =EC10-EB10-EG10-EI10-EK10-(AN10*K10+BB10*L10+BP10*IF(AND(M10>0,M10<1),1,IF(M10>1,MAX(M10,N10/1000),N10))+CD10+CE10*K10+CV10+CW10*L10+DN10+DO10*IF(AND(M10>0,M10<1),1,IF(M10>1,MAX(M10,N10/1000),N10))+CG10+CH10*K10+CY10+CZ10*L10+DQ10+DR10*IF(AND(M10>0,M10<1),1,IF(M10>1,MAX(M10,N10/1000),N10)))-EL10-EM10*EN10/365*ES10%-EO10*EP10/365*ES10% -> 0 | ER10: 23300 | ES10: 7.5
A11: 6 | EB11: =AB11+AC11*K11+AD11*K11+((AF11+AG11+AH11+AJ11+AK11)*K11+AE11+AI11+AL11*K11+AM11*K11)+AP11+AQ11*L11+AR11*L11+((AT11+AU11+AV11+AX11+AY11)*L11+AS11+AW11+AZ11*L11+BA11*L11)+IF(AND(M11>0,MAX(M11,N11/1000)<1),BD11+1*(BE11+BF11)+(1*(BH11+BI11+BJ11+BL11+BM11)+BG11+BK11+BN11+BO11),IF(AND(M11>0,MAX(M11,N11/1000)>1),BD11+MAX(M11,N11/1000)*(BE11+BF11)+(MAX(M11,N11/1000)*(BH11+BI11+BJ11+BL11+BM11)+BG11+BK11+BN11+BO11),IF(AND(K11="",L11="",M11=""),BD11+N11*(BE11+BF11)+((BH11+BI11+BJ11+BL11+BM11)*N11+BG11+BK11+BN11+BO11),0))) -> 0 | EC11: =BR11+BS11*K11+BT11*K11+((BV11+BW11+BX11+BZ11+CA11)*K11+BU11+BY11+CB11*K11+CC11*K11)+CJ11+CK11*L11+CL11*L11+((CN11+CO11+CP11+CR11+CS11)*L11+CM11+CQ11+CT11*L11+CU11*L11)+IF(AND(M11>0,MAX(M11,N11/1000)<1),DB11+1*(DC11+DD11)+(1*(DF11+DG11+DH11+DJ11+DK11)+DE11+DI11+DL11+DM11),IF(AND(M11>0,MAX(M11,N11/1000)>1),DB11+MAX(M11,N11/1000)*(DC11+DD11)+(MAX(M11,N11/1000)*(DF11+DG11+DH11+DJ11+DK11)+DE11+DI11+DL11+DM11),IF(AND(K11="",L11="",M11=""),DB11+N11*(DC11+DD11)+((DF11+DG11+DH11+DJ11+DK11)*N11+DE11+DI11+DL11+DM11),0))) -> 0 | ED11: =AN11*K11*(1-AO11%)+BB11*L11*(1-BC11%)+BP11*IF(AND(M11>0,M11<1),1,IF(M11>1,MAX(M11,N11/1000),N11))*(1-BQ11%) -> 0 | EE11: =(CD11+CE11*K11)*(1-CF11%)+(CG11+CH11*K11)*(1-CI11%)+(CV11+CW11*L11)*(1-CX11%)+(CY11+CZ11*L11)*(1-DA11%)+(DN11+DO11*IF(AND(M11>0,M11<1),1,IF(M11>1,MAX(M11,N11/1000),N11)))*(1-DP11%)+(DQ11+DR11*IF(AND(M11>0,M11<1),1,IF(M11>1,MAX(M11,N11/1000),N11)))*(1-DS11%) -> 0 | EG11: =((BR11+BS11*K11+BT11*K11)+(CJ11+CK11*L11*+CL11*L11)+IF(AND(M11>0,MAX(M11,N11/1000)<1),DB11+DC11+DD11,IF(AND(M11>0,MAX(M11,N11/1000)>1),DB11+DC11*M11+DD11*M11,IF(AND(M11>0,MAX(M11,N11/1000)>1),DB11+MAX(M11,N11/1000)*DC11+MAX(M11,N11/1000)*DD11+IF(AND(K11="",L11="",M11=""),DB11+DC11*N11+DD11*N11,0)))))*EF11/365*ES11% -> 0 | EI11: =(((BV11+BW11+BX11+BZ11+CA11)*K11+BU11+BY11)*1.08+CJ11+CK11*L11+CL11*L11+((CN11+CO11+CP11+CR11+CS11)*L11+CM11+CQ11)*1.08+IF(AND(M11>0,MAX(M11,N11/1000)<1),DB11+1*(DC11+DD11)+(1*(DF11+DG11+DH11+DJ11+DK11)+DE11+DI11)*1.08,IF(AND(M11>0,MAX(M11,N11/1000)>1),DB11+MAX(M11,N11/1000)*(DC11+DD11)+(MAX(M11,N11/1000)*(DF11+DG11+DH11+DJ11+DK11)+DE11+DI11)*1.08,IF(AND(K11="",L11="",M11=""),DB11+N11*(DC11+DD11)+((DF11+DG11+DH11+DJ11+DK11)*N11+DE11+DI11)*1.08,0))))*EH11/365*ES11% -> 0 | EK11: =((CB11*K11+CC11*K11)*1.1+(CT11*L11+CU11*L11)*1.1+(DL11+DM11)*1.1)*EJ11/365*ES11% -> 0 | EQ11: =EC11-EB11-EG11-EI11-EK11-(AN11*K11+BB11*L11+BP11*IF(AND(M11>0,M11<1),1,IF(M11>1,MAX(M11,N11/1000),N11))+CD11+CE11*K11+CV11+CW11*L11+DN11+DO11*IF(AND(M11>0,M11<1),1,IF(M11>1,MAX(M11,N11/1000),N11))+CG11+CH11*K11+CY11+CZ11*L11+DQ11+DR11*IF(AND(M11>0,M11<1),1,IF(M11>1,MAX(M11,N11/1000),N11)))-EL11-EM11*EN11/365*ES11%-EO11*EP11/365*ES11% -> 0 | ER11: 23300 | ES11: 7.5
A12: 7 | EB12: =AB12+AC12*K12+AD12*K12+((AF12+AG12+AH12+AJ12+AK12)*K12+AE12+AI12+AL12*K12+AM12*K12)+AP12+AQ12*L12+AR12*L12+((AT12+AU12+AV12+AX12+AY12)*L12+AS12+AW12+AZ12*L12+BA12*L12)+IF(AND(M12>0,MAX(M12,N12/1000)<1),BD12+1*(BE12+BF12)+(1*(BH12+BI12+BJ12+BL12+BM12)+BG12+BK12+BN12+BO12),IF(AND(M12>0,MAX(M12,N12/1000)>1),BD12+MAX(M12,N12/1000)*(BE12+BF12)+(MAX(M12,N12/1000)*(BH12+BI12+BJ12+BL12+BM12)+BG12+BK12+BN12+BO12),IF(AND(K12="",L12="",M12=""),BD12+N12*(BE12+BF12)+((BH12+BI12+BJ12+BL12+BM12)*N12+BG12+BK12+BN12+BO12),0))) -> 0 | EC12: =BR12+BS12*K12+BT12*K12+((BV12+BW12+BX12+BZ12+CA12)*K12+BU12+BY12+CB12*K12+CC12*K12)+CJ12+CK12*L12+CL12*L12+((CN12+CO12+CP12+CR12+CS12)*L12+CM12+CQ12+CT12*L12+CU12*L12)+IF(AND(M12>0,MAX(M12,N12/1000)<1),DB12+1*(DC12+DD12)+(1*(DF12+DG12+DH12+DJ12+DK12)+DE12+DI12+DL12+DM12),IF(AND(M12>0,MAX(M12,N12/1000)>1),DB12+MAX(M12,N12/1000)*(DC12+DD12)+(MAX(M12,N12/1000)*(DF12+DG12+DH12+DJ12+DK12)+DE12+DI12+DL12+DM12),IF(AND(K12="",L12="",M12=""),DB12+N12*(DC12+DD12)+((DF12+DG12+DH12+DJ12+DK12)*N12+DE12+DI12+DL12+DM12),0))) -> 0 | ED12: =AN12*K12*(1-AO12%)+BB12*L12*(1-BC12%)+BP12*IF(AND(M12>0,M12<1),1,IF(M12>1,MAX(M12,N12/1000),N12))*(1-BQ12%) -> 0 | EE12: =(CD12+CE12*K12)*(1-CF12%)+(CG12+CH12*K12)*(1-CI12%)+(CV12+CW12*L12)*(1-CX12%)+(CY12+CZ12*L12)*(1-DA12%)+(DN12+DO12*IF(AND(M12>0,M12<1),1,IF(M12>1,MAX(M12,N12/1000),N12)))*(1-DP12%)+(DQ12+DR12*IF(AND(M12>0,M12<1),1,IF(M12>1,MAX(M12,N12/1000),N12)))*(1-DS12%) -> 0 | EG12: =((BR12+BS12*K12+BT12*K12)+(CJ12+CK12*L12*+CL12*L12)+IF(AND(M12>0,MAX(M12,N12/1000)<1),DB12+DC12+DD12,IF(AND(M12>0,MAX(M12,N12/1000)>1),DB12+DC12*M12+DD12*M12,IF(AND(M12>0,MAX(M12,N12/1000)>1),DB12+MAX(M12,N12/1000)*DC12+MAX(M12,N12/1000)*DD12+IF(AND(K12="",L12="",M12=""),DB12+DC12*N12+DD12*N12,0)))))*EF12/365*ES12% -> 0 | EI12: =(((BV12+BW12+BX12+BZ12+CA12)*K12+BU12+BY12)*1.08+CJ12+CK12*L12+CL12*L12+((CN12+CO12+CP12+CR12+CS12)*L12+CM12+CQ12)*1.08+IF(AND(M12>0,MAX(M12,N12/1000)<1),DB12+1*(DC12+DD12)+(1*(DF12+DG12+DH12+DJ12+DK12)+DE12+DI12)*1.08,IF(AND(M12>0,MAX(M12,N12/1000)>1),DB12+MAX(M12,N12/1000)*(DC12+DD12)+(MAX(M12,N12/1000)*(DF12+DG12+DH12+DJ12+DK12)+DE12+DI12)*1.08,IF(AND(K12="",L12="",M12=""),DB12+N12*(DC12+DD12)+((DF12+DG12+DH12+DJ12+DK12)*N12+DE12+DI12)*1.08,0))))*EH12/365*ES12% -> 0 | EK12: =((CB12*K12+CC12*K12)*1.1+(CT12*L12+CU12*L12)*1.1+(DL12+DM12)*1.1)*EJ12/365*ES12% -> 0 | EQ12: =EC12-EB12-EG12-EI12-EK12-(AN12*K12+BB12*L12+BP12*IF(AND(M12>0,M12<1),1,IF(M12>1,MAX(M12,N12/1000),N12))+CD12+CE12*K12+CV12+CW12*L12+DN12+DO12*IF(AND(M12>0,M12<1),1,IF(M12>1,MAX(M12,N12/1000),N12))+CG12+CH12*K12+CY12+CZ12*L12+DQ12+DR12*IF(AND(M12>0,M12<1),1,IF(M12>1,MAX(M12,N12/1000),N12)))-EL12-EM12*EN12/365*ES12%-EO12*EP12/365*ES12% -> 0 | ER12: 23300 | ES12: 7.5
A13: 8 | EB13: =AB13+AC13*K13+AD13*K13+((AF13+AG13+AH13+AJ13+AK13)*K13+AE13+AI13+AL13*K13+AM13*K13)+AP13+AQ13*L13+AR13*L13+((AT13+AU13+AV13+AX13+AY13)*L13+AS13+AW13+AZ13*L13+BA13*L13)+IF(AND(M13>0,MAX(M13,N13/1000)<1),BD13+1*(BE13+BF13)+(1*(BH13+BI13+BJ13+BL13+BM13)+BG13+BK13+BN13+BO13),IF(AND(M13>0,MAX(M13,N13/1000)>1),BD13+MAX(M13,N13/1000)*(BE13+BF13)+(MAX(M13,N13/1000)*(BH13+BI13+BJ13+BL13+BM13)+BG13+BK13+BN13+BO13),IF(AND(K13="",L13="",M13=""),BD13+N13*(BE13+BF13)+((BH13+BI13+BJ13+BL13+BM13)*N13+BG13+BK13+BN13+BO13),0))) -> 0 | EC13: =BR13+BS13*K13+BT13*K13+((BV13+BW13+BX13+BZ13+CA13)*K13+BU13+BY13+CB13*K13+CC13*K13)+CJ13+CK13*L13+CL13*L13+((CN13+CO13+CP13+CR13+CS13)*L13+CM13+CQ13+CT13*L13+CU13*L13)+IF(AND(M13>0,MAX(M13,N13/1000)<1),DB13+1*(DC13+DD13)+(1*(DF13+DG13+DH13+DJ13+DK13)+DE13+DI13+DL13+DM13),IF(AND(M13>0,MAX(M13,N13/1000)>1),DB13+MAX(M13,N13/1000)*(DC13+DD13)+(MAX(M13,N13/1000)*(DF13+DG13+DH13+DJ13+DK13)+DE13+DI13+DL13+DM13),IF(AND(K13="",L13="",M13=""),DB13+N13*(DC13+DD13)+((DF13+DG13+DH13+DJ13+DK13)*N13+DE13+DI13+DL13+DM13),0))) -> 0 | ED13: =AN13*K13*(1-AO13%)+BB13*L13*(1-BC13%)+BP13*IF(AND(M13>0,M13<1),1,IF(M13>1,MAX(M13,N13/1000),N13))*(1-BQ13%) -> 0 | EE13: =(CD13+CE13*K13)*(1-CF13%)+(CG13+CH13*K13)*(1-CI13%)+(CV13+CW13*L13)*(1-CX13%)+(CY13+CZ13*L13)*(1-DA13%)+(DN13+DO13*IF(AND(M13>0,M13<1),1,IF(M13>1,MAX(M13,N13/1000),N13)))*(1-DP13%)+(DQ13+DR13*IF(AND(M13>0,M13<1),1,IF(M13>1,MAX(M13,N13/1000),N13)))*(1-DS13%) -> 0 | EG13: =((BR13+BS13*K13+BT13*K13)+(CJ13+CK13*L13*+CL13*L13)+IF(AND(M13>0,MAX(M13,N13/1000)<1),DB13+DC13+DD13,IF(AND(M13>0,MAX(M13,N13/1000)>1),DB13+DC13*M13+DD13*M13,IF(AND(M13>0,MAX(M13,N13/1000)>1),DB13+MAX(M13,N13/1000)*DC13+MAX(M13,N13/1000)*DD13+IF(AND(K13="",L13="",M13=""),DB13+DC13*N13+DD13*N13,0)))))*EF13/365*ES13% -> 0 | EI13: =(((BV13+BW13+BX13+BZ13+CA13)*K13+BU13+BY13)*1.08+CJ13+CK13*L13+CL13*L13+((CN13+CO13+CP13+CR13+CS13)*L13+CM13+CQ13)*1.08+IF(AND(M13>0,MAX(M13,N13/1000)<1),DB13+1*(DC13+DD13)+(1*(DF13+DG13+DH13+DJ13+DK13)+DE13+DI13)*1.08,IF(AND(M13>0,MAX(M13,N13/1000)>1),DB13+MAX(M13,N13/1000)*(DC13+DD13)+(MAX(M13,N13/1000)*(DF13+DG13+DH13+DJ13+DK13)+DE13+DI13)*1.08,IF(AND(K13="",L13="",M13=""),DB13+N13*(DC13+DD13)+((DF13+DG13+DH13+DJ13+DK13)*N13+DE13+DI13)*1.08,0))))*EH13/365*ES13% -> 0 | EK13: =((CB13*K13+CC13*K13)*1.1+(CT13*L13+CU13*L13)*1.1+(DL13+DM13)*1.1)*EJ13/365*ES13% -> 0 | EQ13: =EC13-EB13-EG13-EI13-EK13-(AN13*K13+BB13*L13+BP13*IF(AND(M13>0,M13<1),1,IF(M13>1,MAX(M13,N13/1000),N13))+CD13+CE13*K13+CV13+CW13*L13+DN13+DO13*IF(AND(M13>0,M13<1),1,IF(M13>1,MAX(M13,N13/1000),N13))+CG13+CH13*K13+CY13+CZ13*L13+DQ13+DR13*IF(AND(M13>0,M13<1),1,IF(M13>1,MAX(M13,N13/1000),N13)))-EL13-EM13*EN13/365*ES13%-EO13*EP13/365*ES13% -> 0 | ER13: 23300 | ES13: 7.5
A14: 9 | EB14: =AB14+AC14*K14+AD14*K14+((AF14+AG14+AH14+AJ14+AK14)*K14+AE14+AI14+AL14*K14+AM14*K14)+AP14+AQ14*L14+AR14*L14+((AT14+AU14+AV14+AX14+AY14)*L14+AS14+AW14+AZ14*L14+BA14*L14)+IF(AND(M14>0,MAX(M14,N14/1000)<1),BD14+1*(BE14+BF14)+(1*(BH14+BI14+BJ14+BL14+BM14)+BG14+BK14+BN14+BO14),IF(AND(M14>0,MAX(M14,N14/1000)>1),BD14+MAX(M14,N14/1000)*(BE14+BF14)+(MAX(M14,N14/1000)*(BH14+BI14+BJ14+BL14+BM14)+BG14+BK14+BN14+BO14),IF(AND(K14="",L14="",M14=""),BD14+N14*(BE14+BF14)+((BH14+BI14+BJ14+BL14+BM14)*N14+BG14+BK14+BN14+BO14),0))) -> 0 | EC14: =BR14+BS14*K14+BT14*K14+((BV14+BW14+BX14+BZ14+CA14)*K14+BU14+BY14+CB14*K14+CC14*K14)+CJ14+CK14*L14+CL14*L14+((CN14+CO14+CP14+CR14+CS14)*L14+CM14+CQ14+CT14*L14+CU14*L14)+IF(AND(M14>0,MAX(M14,N14/1000)<1),DB14+1*(DC14+DD14)+(1*(DF14+DG14+DH14+DJ14+DK14)+DE14+DI14+DL14+DM14),IF(AND(M14>0,MAX(M14,N14/1000)>1),DB14+MAX(M14,N14/1000)*(DC14+DD14)+(MAX(M14,N14/1000)*(DF14+DG14+DH14+DJ14+DK14)+DE14+DI14+DL14+DM14),IF(AND(K14="",L14="",M14=""),DB14+N14*(DC14+DD14)+((DF14+DG14+DH14+DJ14+DK14)*N14+DE14+DI14+DL14+DM14),0))) -> 0 | ED14: =AN14*K14*(1-AO14%)+BB14*L14*(1-BC14%)+BP14*IF(AND(M14>0,M14<1),1,IF(M14>1,MAX(M14,N14/1000),N14))*(1-BQ14%) -> 0 | EE14: =(CD14+CE14*K14)*(1-CF14%)+(CG14+CH14*K14)*(1-CI14%)+(CV14+CW14*L14)*(1-CX14%)+(CY14+CZ14*L14)*(1-DA14%)+(DN14+DO14*IF(AND(M14>0,M14<1),1,IF(M14>1,MAX(M14,N14/1000),N14)))*(1-DP14%)+(DQ14+DR14*IF(AND(M14>0,M14<1),1,IF(M14>1,MAX(M14,N14/1000),N14)))*(1-DS14%) -> 0 | EG14: =((BR14+BS14*K14+BT14*K14)+(CJ14+CK14*L14*+CL14*L14)+IF(AND(M14>0,MAX(M14,N14/1000)<1),DB14+DC14+DD14,IF(AND(M14>0,MAX(M14,N14/1000)>1),DB14+DC14*M14+DD14*M14,IF(AND(M14>0,MAX(M14,N14/1000)>1),DB14+MAX(M14,N14/1000)*DC14+MAX(M14,N14/1000)*DD14+IF(AND(K14="",L14="",M14=""),DB14+DC14*N14+DD14*N14,0)))))*EF14/365*ES14% -> 0 | EI14: =(((BV14+BW14+BX14+BZ14+CA14)*K14+BU14+BY14)*1.08+CJ14+CK14*L14+CL14*L14+((CN14+CO14+CP14+CR14+CS14)*L14+CM14+CQ14)*1.08+IF(AND(M14>0,MAX(M14,N14/1000)<1),DB14+1*(DC14+DD14)+(1*(DF14+DG14+DH14+DJ14+DK14)+DE14+DI14)*1.08,IF(AND(M14>0,MAX(M14,N14/1000)>1),DB14+MAX(M14,N14/1000)*(DC14+DD14)+(MAX(M14,N14/1000)*(DF14+DG14+DH14+DJ14+DK14)+DE14+DI14)*1.08,IF(AND(K14="",L14="",M14=""),DB14+N14*(DC14+DD14)+((DF14+DG14+DH14+DJ14+DK14)*N14+DE14+DI14)*1.08,0))))*EH14/365*ES14% -> 0 | EK14: =((CB14*K14+CC14*K14)*1.1+(CT14*L14+CU14*L14)*1.1+(DL14+DM14)*1.1)*EJ14/365*ES14% -> 0 | EQ14: =EC14-EB14-EG14-EI14-EK14-(AN14*K14+BB14*L14+BP14*IF(AND(M14>0,M14<1),1,IF(M14>1,MAX(M14,N14/1000),N14))+CD14+CE14*K14+CV14+CW14*L14+DN14+DO14*IF(AND(M14>0,M14<1),1,IF(M14>1,MAX(M14,N14/1000),N14))+CG14+CH14*K14+CY14+CZ14*L14+DQ14+DR14*IF(AND(M14>0,M14<1),1,IF(M14>1,MAX(M14,N14/1000),N14)))-EL14-EM14*EN14/365*ES14%-EO14*EP14/365*ES14% -> 0 | ER14: 23300 | ES14: 7.5
A15: 10 | EB15: =AB15+AC15*K15+AD15*K15+((AF15+AG15+AH15+AJ15+AK15)*K15+AE15+AI15+AL15*K15+AM15*K15)+AP15+AQ15*L15+AR15*L15+((AT15+AU15+AV15+AX15+AY15)*L15+AS15+AW15+AZ15*L15+BA15*L15)+IF(AND(M15>0,MAX(M15,N15/1000)<1),BD15+1*(BE15+BF15)+(1*(BH15+BI15+BJ15+BL15+BM15)+BG15+BK15+BN15+BO15),IF(AND(M15>0,MAX(M15,N15/1000)>1),BD15+MAX(M15,N15/1000)*(BE15+BF15)+(MAX(M15,N15/1000)*(BH15+BI15+BJ15+BL15+BM15)+BG15+BK15+BN15+BO15),IF(AND(K15="",L15="",M15=""),BD15+N15*(BE15+BF15)+((BH15+BI15+BJ15+BL15+BM15)*N15+BG15+BK15+BN15+BO15),0))) -> 0 | EC15: =BR15+BS15*K15+BT15*K15+((BV15+BW15+BX15+BZ15+CA15)*K15+BU15+BY15+CB15*K15+CC15*K15)+CJ15+CK15*L15+CL15*L15+((CN15+CO15+CP15+CR15+CS15)*L15+CM15+CQ15+CT15*L15+CU15*L15)+IF(AND(M15>0,MAX(M15,N15/1000)<1),DB15+1*(DC15+DD15)+(1*(DF15+DG15+DH15+DJ15+DK15)+DE15+DI15+DL15+DM15),IF(AND(M15>0,MAX(M15,N15/1000)>1),DB15+MAX(M15,N15/1000)*(DC15+DD15)+(MAX(M15,N15/1000)*(DF15+DG15+DH15+DJ15+DK15)+DE15+DI15+DL15+DM15),IF(AND(K15="",L15="",M15=""),DB15+N15*(DC15+DD15)+((DF15+DG15+DH15+DJ15+DK15)*N15+DE15+DI15+DL15+DM15),0))) -> 0 | ED15: =AN15*K15*(1-AO15%)+BB15*L15*(1-BC15%)+BP15*IF(AND(M15>0,M15<1),1,IF(M15>1,MAX(M15,N15/1000),N15))*(1-BQ15%) -> 0 | EE15: =(CD15+CE15*K15)*(1-CF15%)+(CG15+CH15*K15)*(1-CI15%)+(CV15+CW15*L15)*(1-CX15%)+(CY15+CZ15*L15)*(1-DA15%)+(DN15+DO15*IF(AND(M15>0,M15<1),1,IF(M15>1,MAX(M15,N15/1000),N15)))*(1-DP15%)+(DQ15+DR15*IF(AND(M15>0,M15<1),1,IF(M15>1,MAX(M15,N15/1000),N15)))*(1-DS15%) -> 0 | EG15: =((BR15+BS15*K15+BT15*K15)+(CJ15+CK15*L15*+CL15*L15)+IF(AND(M15>0,MAX(M15,N15/1000)<1),DB15+DC15+DD15,IF(AND(M15>0,MAX(M15,N15/1000)>1),DB15+DC15*M15+DD15*M15,IF(AND(M15>0,MAX(M15,N15/1000)>1),DB15+MAX(M15,N15/1000)*DC15+MAX(M15,N15/1000)*DD15+IF(AND(K15="",L15="",M15=""),DB15+DC15*N15+DD15*N15,0)))))*EF15/365*ES15% -> 0 | EI15: =(((BV15+BW15+BX15+BZ15+CA15)*K15+BU15+BY15)*1.08+CJ15+CK15*L15+CL15*L15+((CN15+CO15+CP15+CR15+CS15)*L15+CM15+CQ15)*1.08+IF(AND(M15>0,MAX(M15,N15/1000)<1),DB15+1*(DC15+DD15)+(1*(DF15+DG15+DH15+DJ15+DK15)+DE15+DI15)*1.08,IF(AND(M15>0,MAX(M15,N15/1000)>1),DB15+MAX(M15,N15/1000)*(DC15+DD15)+(MAX(M15,N15/1000)*(DF15+DG15+DH15+DJ15+DK15)+DE15+DI15)*1.08,IF(AND(K15="",L15="",M15=""),DB15+N15*(DC15+DD15)+((DF15+DG15+DH15+DJ15+DK15)*N15+DE15+DI15)*1.08,0))))*EH15/365*ES15% -> 0 | EK15: =((CB15*K15+CC15*K15)*1.1+(CT15*L15+CU15*L15)*1.1+(DL15+DM15)*1.1)*EJ15/365*ES15% -> 0 | EQ15: =EC15-EB15-EG15-EI15-EK15-(AN15*K15+BB15*L15+BP15*IF(AND(M15>0,M15<1),1,IF(M15>1,MAX(M15,N15/1000),N15))+CD15+CE15*K15+CV15+CW15*L15+DN15+DO15*IF(AND(M15>0,M15<1),1,IF(M15>1,MAX(M15,N15/1000),N15))+CG15+CH15*K15+CY15+CZ15*L15+DQ15+DR15*IF(AND(M15>0,M15<1),1,IF(M15>1,MAX(M15,N15/1000),N15)))-EL15-EM15*EN15/365*ES15%-EO15*EP15/365*ES15% -> 0 | ER15: 23300 | ES15: 7.5
A16: 11 | EB16: =AB16+AC16*K16+AD16*K16+((AF16+AG16+AH16+AJ16+AK16)*K16+AE16+AI16+AL16*K16+AM16*K16)+AP16+AQ16*L16+AR16*L16+((AT16+AU16+AV16+AX16+AY16)*L16+AS16+AW16+AZ16*L16+BA16*L16)+IF(AND(M16>0,MAX(M16,N16/1000)<1),BD16+1*(BE16+BF16)+(1*(BH16+BI16+BJ16+BL16+BM16)+BG16+BK16+BN16+BO16),IF(AND(M16>0,MAX(M16,N16/1000)>1),BD16+MAX(M16,N16/1000)*(BE16+BF16)+(MAX(M16,N16/1000)*(BH16+BI16+BJ16+BL16+BM16)+BG16+BK16+BN16+BO16),IF(AND(K16="",L16="",M16=""),BD16+N16*(BE16+BF16)+((BH16+BI16+BJ16+BL16+BM16)*N16+BG16+BK16+BN16+BO16),0))) -> 0 | EC16: =BR16+BS16*K16+BT16*K16+((BV16+BW16+BX16+BZ16+CA16)*K16+BU16+BY16+CB16*K16+CC16*K16)+CJ16+CK16*L16+CL16*L16+((CN16+CO16+CP16+CR16+CS16)*L16+CM16+CQ16+CT16*L16+CU16*L16)+IF(AND(M16>0,MAX(M16,N16/1000)<1),DB16+1*(DC16+DD16)+(1*(DF16+DG16+DH16+DJ16+DK16)+DE16+DI16+DL16+DM16),IF(AND(M16>0,MAX(M16,N16/1000)>1),DB16+MAX(M16,N16/1000)*(DC16+DD16)+(MAX(M16,N16/1000)*(DF16+DG16+DH16+DJ16+DK16)+DE16+DI16+DL16+DM16),IF(AND(K16="",L16="",M16=""),DB16+N16*(DC16+DD16)+((DF16+DG16+DH16+DJ16+DK16)*N16+DE16+DI16+DL16+DM16),0))) -> 0 | ED16: =AN16*K16*(1-AO16%)+BB16*L16*(1-BC16%)+BP16*IF(AND(M16>0,M16<1),1,IF(M16>1,MAX(M16,N16/1000),N16))*(1-BQ16%) -> 0 | EE16: =(CD16+CE16*K16)*(1-CF16%)+(CG16+CH16*K16)*(1-CI16%)+(CV16+CW16*L16)*(1-CX16%)+(CY16+CZ16*L16)*(1-DA16%)+(DN16+DO16*IF(AND(M16>0,M16<1),1,IF(M16>1,MAX(M16,N16/1000),N16)))*(1-DP16%)+(DQ16+DR16*IF(AND(M16>0,M16<1),1,IF(M16>1,MAX(M16,N16/1000),N16)))*(1-DS16%) -> 0 | EG16: =((BR16+BS16*K16+BT16*K16)+(CJ16+CK16*L16*+CL16*L16)+IF(AND(M16>0,MAX(M16,N16/1000)<1),DB16+DC16+DD16,IF(AND(M16>0,MAX(M16,N16/1000)>1),DB16+DC16*M16+DD16*M16,IF(AND(M16>0,MAX(M16,N16/1000)>1),DB16+MAX(M16,N16/1000)*DC16+MAX(M16,N16/1000)*DD16+IF(AND(K16="",L16="",M16=""),DB16+DC16*N16+DD16*N16,0)))))*EF16/365*ES16% -> 0 | EI16: =(((BV16+BW16+BX16+BZ16+CA16)*K16+BU16+BY16)*1.08+CJ16+CK16*L16+CL16*L16+((CN16+CO16+CP16+CR16+CS16)*L16+CM16+CQ16)*1.08+IF(AND(M16>0,MAX(M16,N16/1000)<1),DB16+1*(DC16+DD16)+(1*(DF16+DG16+DH16+DJ16+DK16)+DE16+DI16)*1.08,IF(AND(M16>0,MAX(M16,N16/1000)>1),DB16+MAX(M16,N16/1000)*(DC16+DD16)+(MAX(M16,N16/1000)*(DF16+DG16+DH16+DJ16+DK16)+DE16+DI16)*1.08,IF(AND(K16="",L16="",M16=""),DB16+N16*(DC16+DD16)+((DF16+DG16+DH16+DJ16+DK16)*N16+DE16+DI16)*1.08,0))))*EH16/365*ES16% -> 0 | EK16: =((CB16*K16+CC16*K16)*1.1+(CT16*L16+CU16*L16)*1.1+(DL16+DM16)*1.1)*EJ16/365*ES16% -> 0 | EQ16: =EC16-EB16-EG16-EI16-EK16-(AN16*K16+BB16*L16+BP16*IF(AND(M16>0,M16<1),1,IF(M16>1,MAX(M16,N16/1000),N16))+CD16+CE16*K16+CV16+CW16*L16+DN16+DO16*IF(AND(M16>0,M16<1),1,IF(M16>1,MAX(M16,N16/1000),N16))+CG16+CH16*K16+CY16+CZ16*L16+DQ16+DR16*IF(AND(M16>0,M16<1),1,IF(M16>1,MAX(M16,N16/1000),N16)))-EL16-EM16*EN16/365*ES16%-EO16*EP16/365*ES16% -> 0 | ER16: 23300 | ES16: 7.5
A17: 12 | EB17: =AB17+AC17*K17+AD17*K17+((AF17+AG17+AH17+AJ17+AK17)*K17+AE17+AI17+AL17*K17+AM17*K17)+AP17+AQ17*L17+AR17*L17+((AT17+AU17+AV17+AX17+AY17)*L17+AS17+AW17+AZ17*L17+BA17*L17)+IF(AND(M17>0,MAX(M17,N17/1000)<1),BD17+1*(BE17+BF17)+(1*(BH17+BI17+BJ17+BL17+BM17)+BG17+BK17+BN17+BO17),IF(AND(M17>0,MAX(M17,N17/1000)>1),BD17+MAX(M17,N17/1000)*(BE17+BF17)+(MAX(M17,N17/1000)*(BH17+BI17+BJ17+BL17+BM17)+BG17+BK17+BN17+BO17),IF(AND(K17="",L17="",M17=""),BD17+N17*(BE17+BF17)+((BH17+BI17+BJ17+BL17+BM17)*N17+BG17+BK17+BN17+BO17),0))) -> 0 | EC17: =BR17+BS17*K17+BT17*K17+((BV17+BW17+BX17+BZ17+CA17)*K17+BU17+BY17+CB17*K17+CC17*K17)+CJ17+CK17*L17+CL17*L17+((CN17+CO17+CP17+CR17+CS17)*L17+CM17+CQ17+CT17*L17+CU17*L17)+IF(AND(M17>0,MAX(M17,N17/1000)<1),DB17+1*(DC17+DD17)+(1*(DF17+DG17+DH17+DJ17+DK17)+DE17+DI17+DL17+DM17),IF(AND(M17>0,MAX(M17,N17/1000)>1),DB17+MAX(M17,N17/1000)*(DC17+DD17)+(MAX(M17,N17/1000)*(DF17+DG17+DH17+DJ17+DK17)+DE17+DI17+DL17+DM17),IF(AND(K17="",L17="",M17=""),DB17+N17*(DC17+DD17)+((DF17+DG17+DH17+DJ17+DK17)*N17+DE17+DI17+DL17+DM17),0))) -> 0 | ED17: =AN17*K17*(1-AO17%)+BB17*L17*(1-BC17%)+BP17*IF(AND(M17>0,M17<1),1,IF(M17>1,MAX(M17,N17/1000),N17))*(1-BQ17%) -> 0 | EE17: =(CD17+CE17*K17)*(1-CF17%)+(CG17+CH17*K17)*(1-CI17%)+(CV17+CW17*L17)*(1-CX17%)+(CY17+CZ17*L17)*(1-DA17%)+(DN17+DO17*IF(AND(M17>0,M17<1),1,IF(M17>1,MAX(M17,N17/1000),N17)))*(1-DP17%)+(DQ17+DR17*IF(AND(M17>0,M17<1),1,IF(M17>1,MAX(M17,N17/1000),N17)))*(1-DS17%) -> 0 | EG17: =((BR17+BS17*K17+BT17*K17)+(CJ17+CK17*L17*+CL17*L17)+IF(AND(M17>0,MAX(M17,N17/1000)<1),DB17+DC17+DD17,IF(AND(M17>0,MAX(M17,N17/1000)>1),DB17+DC17*M17+DD17*M17,IF(AND(M17>0,MAX(M17,N17/1000)>1),DB17+MAX(M17,N17/1000)*DC17+MAX(M17,N17/1000)*DD17+IF(AND(K17="",L17="",M17=""),DB17+DC17*N17+DD17*N17,0)))))*EF17/365*ES17% -> 0 | EI17: =(((BV17+BW17+BX17+BZ17+CA17)*K17+BU17+BY17)*1.08+CJ17+CK17*L17+CL17*L17+((CN17+CO17+CP17+CR17+CS17)*L17+CM17+CQ17)*1.08+IF(AND(M17>0,MAX(M17,N17/1000)<1),DB17+1*(DC17+DD17)+(1*(DF17+DG17+DH17+DJ17+DK17)+DE17+DI17)*1.08,IF(AND(M17>0,MAX(M17,N17/1000)>1),DB17+MAX(M17,N17/1000)*(DC17+DD17)+(MAX(M17,N17/1000)*(DF17+DG17+DH17+DJ17+DK17)+DE17+DI17)*1.08,IF(AND(K17="",L17="",M17=""),DB17+N17*(DC17+DD17)+((DF17+DG17+DH17+DJ17+DK17)*N17+DE17+DI17)*1.08,0))))*EH17/365*ES17% -> 0 | EK17: =((CB17*K17+CC17*K17)*1.1+(CT17*L17+CU17*L17)*1.1+(DL17+DM17)*1.1)*EJ17/365*ES17% -> 0 | EQ17: =EC17-EB17-EG17-EI17-EK17-(AN17*K17+BB17*L17+BP17*IF(AND(M17>0,M17<1),1,IF(M17>1,MAX(M17,N17/1000),N17))+CD17+CE17*K17+CV17+CW17*L17+DN17+DO17*IF(AND(M17>0,M17<1),1,IF(M17>1,MAX(M17,N17/1000),N17))+CG17+CH17*K17+CY17+CZ17*L17+DQ17+DR17*IF(AND(M17>0,M17<1),1,IF(M17>1,MAX(M17,N17/1000),N17)))-EL17-EM17*EN17/365*ES17%-EO17*EP17/365*ES17% -> 0 | ER17: 23300 | ES17: 7.5
A18: 13 | EB18: =AB18+AC18*K18+AD18*K18+((AF18+AG18+AH18+AJ18+AK18)*K18+AE18+AI18+AL18*K18+AM18*K18)+AP18+AQ18*L18+AR18*L18+((AT18+AU18+AV18+AX18+AY18)*L18+AS18+AW18+AZ18*L18+BA18*L18)+IF(AND(M18>0,MAX(M18,N18/1000)<1),BD18+1*(BE18+BF18)+(1*(BH18+BI18+BJ18+BL18+BM18)+BG18+BK18+BN18+BO18),IF(AND(M18>0,MAX(M18,N18/1000)>1),BD18+MAX(M18,N18/1000)*(BE18+BF18)+(MAX(M18,N18/1000)*(BH18+BI18+BJ18+BL18+BM18)+BG18+BK18+BN18+BO18),IF(AND(K18="",L18="",M18=""),BD18+N18*(BE18+BF18)+((BH18+BI18+BJ18+BL18+BM18)*N18+BG18+BK18+BN18+BO18),0))) -> 0 | EC18: =BR18+BS18*K18+BT18*K18+((BV18+BW18+BX18+BZ18+CA18)*K18+BU18+BY18+CB18*K18+CC18*K18)+CJ18+CK18*L18+CL18*L18+((CN18+CO18+CP18+CR18+CS18)*L18+CM18+CQ18+CT18*L18+CU18*L18)+IF(AND(M18>0,MAX(M18,N18/1000)<1),DB18+1*(DC18+DD18)+(1*(DF18+DG18+DH18+DJ18+DK18)+DE18+DI18+DL18+DM18),IF(AND(M18>0,MAX(M18,N18/1000)>1),DB18+MAX(M18,N18/1000)*(DC18+DD18)+(MAX(M18,N18/1000)*(DF18+DG18+DH18+DJ18+DK18)+DE18+DI18+DL18+DM18),IF(AND(K18="",L18="",M18=""),DB18+N18*(DC18+DD18)+((DF18+DG18+DH18+DJ18+DK18)*N18+DE18+DI18+DL18+DM18),0))) -> 0 | ED18: =AN18*K18*(1-AO18%)+BB18*L18*(1-BC18%)+BP18*IF(AND(M18>0,M18<1),1,IF(M18>1,MAX(M18,N18/1000),N18))*(1-BQ18%) -> 0 | EE18: =(CD18+CE18*K18)*(1-CF18%)+(CG18+CH18*K18)*(1-CI18%)+(CV18+CW18*L18)*(1-CX18%)+(CY18+CZ18*L18)*(1-DA18%)+(DN18+DO18*IF(AND(M18>0,M18<1),1,IF(M18>1,MAX(M18,N18/1000),N18)))*(1-DP18%)+(DQ18+DR18*IF(AND(M18>0,M18<1),1,IF(M18>1,MAX(M18,N18/1000),N18)))*(1-DS18%) -> 0 | EG18: =((BR18+BS18*K18+BT18*K18)+(CJ18+CK18*L18*+CL18*L18)+IF(AND(M18>0,MAX(M18,N18/1000)<1),DB18+DC18+DD18,IF(AND(M18>0,MAX(M18,N18/1000)>1),DB18+DC18*M18+DD18*M18,IF(AND(M18>0,MAX(M18,N18/1000)>1),DB18+MAX(M18,N18/1000)*DC18+MAX(M18,N18/1000)*DD18+IF(AND(K18="",L18="",M18=""),DB18+DC18*N18+DD18*N18,0)))))*EF18/365*ES18% -> 0 | EI18: =(((BV18+BW18+BX18+BZ18+CA18)*K18+BU18+BY18)*1.08+CJ18+CK18*L18+CL18*L18+((CN18+CO18+CP18+CR18+CS18)*L18+CM18+CQ18)*1.08+IF(AND(M18>0,MAX(M18,N18/1000)<1),DB18+1*(DC18+DD18)+(1*(DF18+DG18+DH18+DJ18+DK18)+DE18+DI18)*1.08,IF(AND(M18>0,MAX(M18,N18/1000)>1),DB18+MAX(M18,N18/1000)*(DC18+DD18)+(MAX(M18,N18/1000)*(DF18+DG18+DH18+DJ18+DK18)+DE18+DI18)*1.08,IF(AND(K18="",L18="",M18=""),DB18+N18*(DC18+DD18)+((DF18+DG18+DH18+DJ18+DK18)*N18+DE18+DI18)*1.08,0))))*EH18/365*ES18% -> 0 | EK18: =((CB18*K18+CC18*K18)*1.1+(CT18*L18+CU18*L18)*1.1+(DL18+DM18)*1.1)*EJ18/365*ES18% -> 0 | EQ18: =EC18-EB18-EG18-EI18-EK18-(AN18*K18+BB18*L18+BP18*IF(AND(M18>0,M18<1),1,IF(M18>1,MAX(M18,N18/1000),N18))+CD18+CE18*K18+CV18+CW18*L18+DN18+DO18*IF(AND(M18>0,M18<1),1,IF(M18>1,MAX(M18,N18/1000),N18))+CG18+CH18*K18+CY18+CZ18*L18+DQ18+DR18*IF(AND(M18>0,M18<1),1,IF(M18>1,MAX(M18,N18/1000),N18)))-EL18-EM18*EN18/365*ES18%-EO18*EP18/365*ES18% -> 0 | ER18: 23300 | ES18: 7.5
A19: 14 | EB19: =AB19+AC19*K19+AD19*K19+((AF19+AG19+AH19+AJ19+AK19)*K19+AE19+AI19+AL19*K19+AM19*K19)+AP19+AQ19*L19+AR19*L19+((AT19+AU19+AV19+AX19+AY19)*L19+AS19+AW19+AZ19*L19+BA19*L19)+IF(AND(M19>0,MAX(M19,N19/1000)<1),BD19+1*(BE19+BF19)+(1*(BH19+BI19+BJ19+BL19+BM19)+BG19+BK19+BN19+BO19),IF(AND(M19>0,MAX(M19,N19/1000)>1),BD19+MAX(M19,N19/1000)*(BE19+BF19)+(MAX(M19,N19/1000)*(BH19+BI19+BJ19+BL19+BM19)+BG19+BK19+BN19+BO19),IF(AND(K19="",L19="",M19=""),BD19+N19*(BE19+BF19)+((BH19+BI19+BJ19+BL19+BM19)*N19+BG19+BK19+BN19+BO19),0))) -> 0 | EC19: =BR19+BS19*K19+BT19*K19+((BV19+BW19+BX19+BZ19+CA19)*K19+BU19+BY19+CB19*K19+CC19*K19)+CJ19+CK19*L19+CL19*L19+((CN19+CO19+CP19+CR19+CS19)*L19+CM19+CQ19+CT19*L19+CU19*L19)+IF(AND(M19>0,MAX(M19,N19/1000)<1),DB19+1*(DC19+DD19)+(1*(DF19+DG19+DH19+DJ19+DK19)+DE19+DI19+DL19+DM19),IF(AND(M19>0,MAX(M19,N19/1000)>1),DB19+MAX(M19,N19/1000)*(DC19+DD19)+(MAX(M19,N19/1000)*(DF19+DG19+DH19+DJ19+DK19)+DE19+DI19+DL19+DM19),IF(AND(K19="",L19="",M19=""),DB19+N19*(DC19+DD19)+((DF19+DG19+DH19+DJ19+DK19)*N19+DE19+DI19+DL19+DM19),0))) -> 0 | ED19: =AN19*K19*(1-AO19%)+BB19*L19*(1-BC19%)+BP19*IF(AND(M19>0,M19<1),1,IF(M19>1,MAX(M19,N19/1000),N19))*(1-BQ19%) -> 0 | EE19: =(CD19+CE19*K19)*(1-CF19%)+(CG19+CH19*K19)*(1-CI19%)+(CV19+CW19*L19)*(1-CX19%)+(CY19+CZ19*L19)*(1-DA19%)+(DN19+DO19*IF(AND(M19>0,M19<1),1,IF(M19>1,MAX(M19,N19/1000),N19)))*(1-DP19%)+(DQ19+DR19*IF(AND(M19>0,M19<1),1,IF(M19>1,MAX(M19,N19/1000),N19)))*(1-DS19%) -> 0 | EG19: =((BR19+BS19*K19+BT19*K19)+(CJ19+CK19*L19*+CL19*L19)+IF(AND(M19>0,MAX(M19,N19/1000)<1),DB19+DC19+DD19,IF(AND(M19>0,MAX(M19,N19/1000)>1),DB19+DC19*M19+DD19*M19,IF(AND(M19>0,MAX(M19,N19/1000)>1),DB19+MAX(M19,N19/1000)*DC19+MAX(M19,N19/1000)*DD19+IF(AND(K19="",L19="",M19=""),DB19+DC19*N19+DD19*N19,0)))))*EF19/365*ES19% -> 0 | EI19: =(((BV19+BW19+BX19+BZ19+CA19)*K19+BU19+BY19)*1.08+CJ19+CK19*L19+CL19*L19+((CN19+CO19+CP19+CR19+CS19)*L19+CM19+CQ19)*1.08+IF(AND(M19>0,MAX(M19,N19/1000)<1),DB19+1*(DC19+DD19)+(1*(DF19+DG19+DH19+DJ19+DK19)+DE19+DI19)*1.08,IF(AND(M19>0,MAX(M19,N19/1000)>1),DB19+MAX(M19,N19/1000)*(DC19+DD19)+(MAX(M19,N19/1000)*(DF19+DG19+DH19+DJ19+DK19)+DE19+DI19)*1.08,IF(AND(K19="",L19="",M19=""),DB19+N19*(DC19+DD19)+((DF19+DG19+DH19+DJ19+DK19)*N19+DE19+DI19)*1.08,0))))*EH19/365*ES19% -> 0 | EK19: =((CB19*K19+CC19*K19)*1.1+(CT19*L19+CU19*L19)*1.1+(DL19+DM19)*1.1)*EJ19/365*ES19% -> 0 | EQ19: =EC19-EB19-EG19-EI19-EK19-(AN19*K19+BB19*L19+BP19*IF(AND(M19>0,M19<1),1,IF(M19>1,MAX(M19,N19/1000),N19))+CD19+CE19*K19+CV19+CW19*L19+DN19+DO19*IF(AND(M19>0,M19<1),1,IF(M19>1,MAX(M19,N19/1000),N19))+CG19+CH19*K19+CY19+CZ19*L19+DQ19+DR19*IF(AND(M19>0,M19<1),1,IF(M19>1,MAX(M19,N19/1000),N19)))-EL19-EM19*EN19/365*ES19%-EO19*EP19/365*ES19% -> 0 | ER19: 23300 | ES19: 7.5
... A385: 380 | EB385: =AB385+AC385*K385+AD385*K385+((AF385+AG385+AH385+AJ385+AK385)*K385+AE385+AI385+AL385*K385+AM385*K385)+AP385+AQ385*L385+AR385*L385+((AT385+AU385+AV385+AX385+AY385)*L385+AS385+AW385+AZ385*L385+BA385*L385)+IF(AND(M385>0,MAX(M385,N385/1000)<1),BD385+1*(BE385+BF385)+(1*(BH385+BI385+BJ385+BL385+BM385)+BG385+BK385+BN385+BO385),IF(AND(M385>0,MAX(M385,N385/1000)>1),BD385+MAX(M385,N385/1000)*(BE385+BF385)+(MAX(M385,N385/1000)*(BH385+BI385+BJ385+BL385+BM385)+BG385+BK385+BN385+BO385),IF(AND(K385="",L385="",M385=""),BD385+N385*(BE385+BF385)+((BH385+BI385+BJ385+BL385+BM385)*N385+BG385+BK385+BN385+BO385),0))) -> 0 | EC385: =BR385+BS385*K385+BT385*K385+((BV385+BW385+BX385+BZ385+CA385)*K385+BU385+BY385+CB385*K385+CC385*K385)+CJ385+CK385*L385+CL385*L385+((CN385+CO385+CP385+CR385+CS385)*L385+CM385+CQ385+CT385*L385+CU385*L385)+IF(AND(M385>0,MAX(M385,N385/1000)<1),DB385+1*(DC385+DD385)+(1*(DF385+DG385+DH385+DJ385+DK385)+DE385+DI385+DL385+DM385),IF(AND(M385>0,MAX(M385,N385/1000)>1),DB385+MAX(M385,N385/1000)*(DC385+DD385)+(MAX(M385,N385/1000)*(DF385+DG385+DH385+DJ385+DK385)+DE385+DI385+DL385+DM385),IF(AND(K385="",L385="",M385=""),DB385+N385*(DC385+DD385)+((DF385+DG385+DH385+DJ385+DK385)*N385+DE385+DI385+DL385+DM385),0))) -> 0 | ED385: =AN385*K385*(1-AO385%)+BB385*L385*(1-BC385%)+BP385*IF(AND(M385>0,M385<1),1,IF(M385>1,MAX(M385,N385/1000),N385))*(1-BQ385%) -> 0 | EE385: =(CD385+CE385*K385)*(1-CF385%)+(CG385+CH385*K385)*(1-CI385%)+(CV385+CW385*L385)*(1-CX385%)+(CY385+CZ385*L385)*(1-DA385%)+(DN385+DO385*IF(AND(M385>0,M385<1),1,IF(M385>1,MAX(M385,N385/1000),N385)))*(1-DP385%)+(DQ385+DR385*IF(AND(M385>0,M385<1),1,IF(M385>1,MAX(M385,N385/1000),N385)))*(1-DS385%) -> 0 | EG385: =((BR385+BS385*K385+BT385*K385)+(CJ385+CK385*L385*+CL385*L385)+IF(AND(M385>0,MAX(M385,N385/1000)<1),DB385+DC385+DD385,IF(AND(M385>0,MAX(M385,N385/1000)>1),DB385+DC385*M385+DD385*M385,IF(AND(M385>0,MAX(M385,N385/1000)>1),DB385+MAX(M385,N385/1000)*DC385+MAX(M385,N385/1000)*DD385+IF(AND(K385="",L385="",M385=""),DB385+DC385*N385+DD385*N385,0)))))*EF385/365*ES385% -> 0 | EI385: =(((BV385+BW385+BX385+BZ385+CA385)*K385+BU385+BY385)*1.08+CJ385+CK385*L385+CL385*L385+((CN385+CO385+CP385+CR385+CS385)*L385+CM385+CQ385)*1.08+IF(AND(M385>0,MAX(M385,N385/1000)<1),DB385+1*(DC385+DD385)+(1*(DF385+DG385+DH385+DJ385+DK385)+DE385+DI385)*1.08,IF(AND(M385>0,MAX(M385,N385/1000)>1),DB385+MAX(M385,N385/1000)*(DC385+DD385)+(MAX(M385,N385/1000)*(DF385+DG385+DH385+DJ385+DK385)+DE385+DI385)*1.08,IF(AND(K385="",L385="",M385=""),DB385+N385*(DC385+DD385)+((DF385+DG385+DH385+DJ385+DK385)*N385+DE385+DI385)*1.08,0))))*EH385/365*ES385% -> 0 | EK385: =((CB385*K385+CC385*K385)*1.1+(CT385*L385+CU385*L385)*1.1+(DL385+DM385)*1.1)*EJ385/365*ES385% -> 0 | EQ385: =EC385-EB385-EG385-EI385-EK385-(AN385*K385+BB385*L385+BP385*IF(AND(M385>0,M385<1),1,IF(M385>1,MAX(M385,N385/1000),N385))+CD385+CE385*K385+CV385+CW385*L385+DN385+DO385*IF(AND(M385>0,M385<1),1,IF(M385>1,MAX(M385,N385/1000),N385))+CG385+CH385*K385+CY385+CZ385*L385+DQ385+DR385*IF(AND(M385>0,M385<1),1,IF(M385>1,MAX(M385,N385/1000),N385)))-EL385-EM385*EN385/365*ES385%-EO385*EP385/365*ES385% -> 0 | ER385: 23300 | ES385: 7.5
EB386: =AB386+AC386*K386+AD386*K386+((AF386+AG386+AH386+AJ386+AK386)*K386+AE386+AI386+AL386*K386+AM386*K386)+AP386+AQ386*L386+AR386*L386+((AT386+AU386+AV386+AX386+AY386)*L386+AS386+AW386+AZ386*L386+BA386*L386)+IF(AND(M386>0,MAX(M386,N386/1000)<1),BD386+1*(BE386+BF386)+(1*(BH386+BI386+BJ386+BL386+BM386)+BG386+BK386+BN386+BO386),IF(AND(M386>0,MAX(M386,N386/1000)>1),BD386+MAX(M386,N386/1000)*(BE386+BF386)+(MAX(M386,N386/1000)*(BH386+BI386+BJ386+BL386+BM386)+BG386+BK386+BN386+BO386),IF(AND(K386="",L386="",M386=""),BD386+N386*(BE386+BF386)+((BH386+BI386+BJ386+BL386+BM386)*N386+BG386+BK386+BN386+BO386),0))) -> 0 | EC386: =BR386+BS386*K386+BT386*K386+((BV386+BW386+BX386+BZ386+CA386)*K386+BU386+BY386+CB386*K386+CC386*K386)+CJ386+CK386*L386+CL386*L386+((CN386+CO386+CP386+CR386+CS386)*L386+CM386+CQ386+CT386*L386+CU386*L386)+IF(AND(M386>0,MAX(M386,N386/1000)<1),DB386+1*(DC386+DD386)+(1*(DF386+DG386+DH386+DJ386+DK386)+DE386+DI386+DL386+DM386),IF(AND(M386>0,MAX(M386,N386/1000)>1),DB386+MAX(M386,N386/1000)*(DC386+DD386)+(MAX(M386,N386/1000)*(DF386+DG386+DH386+DJ386+DK386)+DE386+DI386+DL386+DM386),IF(AND(K386="",L386="",M386=""),DB386+N386*(DC386+DD386)+((DF386+DG386+DH386+DJ386+DK386)*N386+DE386+DI386+DL386+DM386),0))) -> 0 | ED386: =AN386*K386*(1-AO386%)+BB386*L386*(1-BC386%)+BP386*IF(AND(M386>0,M386<1),1,IF(M386>1,MAX(M386,N386/1000),N386))*(1-BQ386%) -> 0 | EE386: =(CD386+CE386*K386)*(1-CF386%)+(CG386+CH386*K386)*(1-CI386%)+(CV386+CW386*L386)*(1-CX386%)+(CY386+CZ386*L386)*(1-DA386%)+(DN386+DO386*IF(AND(M386>0,M386<1),1,IF(M386>1,MAX(M386,N386/1000),N386)))*(1-DP386%)+(DQ386+DR386*IF(AND(M386>0,M386<1),1,IF(M386>1,MAX(M386,N386/1000),N386)))*(1-DS386%) -> 0 | EG386: =((BR386+BS386*K386+BT386*K386)+(CJ386+CK386*L386*+CL386*L386)+IF(AND(M386>0,MAX(M386,N386/1000)<1),DB386+DC386+DD386,IF(AND(M386>0,MAX(M386,N386/1000)>1),DB386+DC386*M386+DD386*M386,IF(AND(M386>0,MAX(M386,N386/1000)>1),DB386+MAX(M386,N386/1000)*DC386+MAX(M386,N386/1000)*DD386+IF(AND(K386="",L386="",M386=""),DB386+DC386*N386+DD386*N386,0)))))*EF386/365*ES386% -> 0 | EI386: =(((BV386+BW386+BX386+BZ386+CA386)*K386+BU386+BY386)*1.08+CJ386+CK386*L386+CL386*L386+((CN386+CO386+CP386+CR386+CS386)*L386+CM386+CQ386)*1.08+IF(AND(M386>0,MAX(M386,N386/1000)<1),DB386+1*(DC386+DD386)+(1*(DF386+DG386+DH386+DJ386+DK386)+DE386+DI386)*1.08,IF(AND(M386>0,MAX(M386,N386/1000)>1),DB386+MAX(M386,N386/1000)*(DC386+DD386)+(MAX(M386,N386/1000)*(DF386+DG386+DH386+DJ386+DK386)+DE386+DI386)*1.08,IF(AND(K386="",L386="",M386=""),DB386+N386*(DC386+DD386)+((DF386+DG386+DH386+DJ386+DK386)*N386+DE386+DI386)*1.08,0))))*EH386/365*ES386% -> 0 | EK386: =((CB386*K386+CC386*K386)*1.1+(CT386*L386+CU386*L386)*1.1+(DL386+DM386)*1.1)*EJ386/365*ES386% -> 0 | EQ386: =EC386-EB386-EG386-EI386-EK386-(AN386*K386+BB386*L386+BP386*IF(AND(M386>0,M386<1),1,IF(M386>1,MAX(M386,N386/1000),N386))+CD386+CE386*K386+CV386+CW386*L386+DN386+DO386*IF(AND(M386>0,M386<1),1,IF(M386>1,MAX(M386,N386/1000),N386))+CG386+CH386*K386+CY386+CZ386*L386+DQ386+DR386*IF(AND(M386>0,M386<1),1,IF(M386>1,MAX(M386,N386/1000),N386)))-EL386-EM386*EN386/365*ES386%-EO386*EP386/365*ES386% -> 0 | ER386: 23300 | ES386: 7.5
EB387: =AB387+AC387*K387+AD387*K387+((AF387+AG387+AH387+AJ387+AK387)*K387+AE387+AI387+AL387*K387+AM387*K387)+AP387+AQ387*L387+AR387*L387+((AT387+AU387+AV387+AX387+AY387)*L387+AS387+AW387+AZ387*L387+BA387*L387)+IF(AND(M387>0,MAX(M387,N387/1000)<1),BD387+1*(BE387+BF387)+(1*(BH387+BI387+BJ387+BL387+BM387)+BG387+BK387+BN387+BO387),IF(AND(M387>0,MAX(M387,N387/1000)>1),BD387+MAX(M387,N387/1000)*(BE387+BF387)+(MAX(M387,N387/1000)*(BH387+BI387+BJ387+BL387+BM387)+BG387+BK387+BN387+BO387),IF(AND(K387="",L387="",M387=""),BD387+N387*(BE387+BF387)+((BH387+BI387+BJ387+BL387+BM387)*N387+BG387+BK387+BN387+BO387),0))) -> 0 | EC387: =BR387+BS387*K387+BT387*K387+((BV387+BW387+BX387+BZ387+CA387)*K387+BU387+BY387+CB387*K387+CC387*K387)+CJ387+CK387*L387+CL387*L387+((CN387+CO387+CP387+CR387+CS387)*L387+CM387+CQ387+CT387*L387+CU387*L387)+IF(AND(M387>0,MAX(M387,N387/1000)<1),DB387+1*(DC387+DD387)+(1*(DF387+DG387+DH387+DJ387+DK387)+DE387+DI387+DL387+DM387),IF(AND(M387>0,MAX(M387,N387/1000)>1),DB387+MAX(M387,N387/1000)*(DC387+DD387)+(MAX(M387,N387/1000)*(DF387+DG387+DH387+DJ387+DK387)+DE387+DI387+DL387+DM387),IF(AND(K387="",L387="",M387=""),DB387+N387*(DC387+DD387)+((DF387+DG387+DH387+DJ387+DK387)*N387+DE387+DI387+DL387+DM387),0))) -> 0 | ED387: =AN387*K387*(1-AO387%)+BB387*L387*(1-BC387%)+BP387*IF(AND(M387>0,M387<1),1,IF(M387>1,MAX(M387,N387/1000),N387))*(1-BQ387%) -> 0 | EE387: =(CD387+CE387*K387)*(1-CF387%)+(CG387+CH387*K387)*(1-CI387%)+(CV387+CW387*L387)*(1-CX387%)+(CY387+CZ387*L387)*(1-DA387%)+(DN387+DO387*IF(AND(M387>0,M387<1),1,IF(M387>1,MAX(M387,N387/1000),N387)))*(1-DP387%)+(DQ387+DR387*IF(AND(M387>0,M387<1),1,IF(M387>1,MAX(M387,N387/1000),N387)))*(1-DS387%) -> 0 | EG387: =((BR387+BS387*K387+BT387*K387)+(CJ387+CK387*L387*+CL387*L387)+IF(AND(M387>0,MAX(M387,N387/1000)<1),DB387+DC387+DD387,IF(AND(M387>0,MAX(M387,N387/1000)>1),DB387+DC387*M387+DD387*M387,IF(AND(M387>0,MAX(M387,N387/1000)>1),DB387+MAX(M387,N387/1000)*DC387+MAX(M387,N387/1000)*DD387+IF(AND(K387="",L387="",M387=""),DB387+DC387*N387+DD387*N387,0)))))*EF387/365*ES387% -> 0 | EI387: =(((BV387+BW387+BX387+BZ387+CA387)*K387+BU387+BY387)*1.08+CJ387+CK387*L387+CL387*L387+((CN387+CO387+CP387+CR387+CS387)*L387+CM387+CQ387)*1.08+IF(AND(M387>0,MAX(M387,N387/1000)<1),DB387+1*(DC387+DD387)+(1*(DF387+DG387+DH387+DJ387+DK387)+DE387+DI387)*1.08,IF(AND(M387>0,MAX(M387,N387/1000)>1),DB387+MAX(M387,N387/1000)*(DC387+DD387)+(MAX(M387,N387/1000)*(DF387+DG387+DH387+DJ387+DK387)+DE387+DI387)*1.08,IF(AND(K387="",L387="",M387=""),DB387+N387*(DC387+DD387)+((DF387+DG387+DH387+DJ387+DK387)*N387+DE387+DI387)*1.08,0))))*EH387/365*ES387% -> 0 | EK387: =((CB387*K387+CC387*K387)*1.1+(CT387*L387+CU387*L387)*1.1+(DL387+DM387)*1.1)*EJ387/365*ES387% -> 0 | EQ387: =EC387-EB387-EG387-EI387-EK387-(AN387*K387+BB387*L387+BP387*IF(AND(M387>0,M387<1),1,IF(M387>1,MAX(M387,N387/1000),N387))+CD387+CE387*K387+CV387+CW387*L387+DN387+DO387*IF(AND(M387>0,M387<1),1,IF(M387>1,MAX(M387,N387/1000),N387))+CG387+CH387*K387+CY387+CZ387*L387+DQ387+DR387*IF(AND(M387>0,M387<1),1,IF(M387>1,MAX(M387,N387/1000),N387)))-EL387-EM387*EN387/365*ES387%-EO387*EP387/365*ES387% -> 0 | ER387: 23300 | ES387: 7.5
EB388: =AB388+AC388*K388+AD388*K388+((AF388+AG388+AH388+AJ388+AK388)*K388+AE388+AI388+AL388*K388+AM388*K388)+AP388+AQ388*L388+AR388*L388+((AT388+AU388+AV388+AX388+AY388)*L388+AS388+AW388+AZ388*L388+BA388*L388)+IF(AND(M388>0,MAX(M388,N388/1000)<1),BD388+1*(BE388+BF388)+(1*(BH388+BI388+BJ388+BL388+BM388)+BG388+BK388+BN388+BO388),IF(AND(M388>0,MAX(M388,N388/1000)>1),BD388+MAX(M388,N388/1000)*(BE388+BF388)+(MAX(M388,N388/1000)*(BH388+BI388+BJ388+BL388+BM388)+BG388+BK388+BN388+BO388),IF(AND(K388="",L388="",M388=""),BD388+N388*(BE388+BF388)+((BH388+BI388+BJ388+BL388+BM388)*N388+BG388+BK388+BN388+BO388),0))) -> 0 | EC388: =BR388+BS388*K388+BT388*K388+((BV388+BW388+BX388+BZ388+CA388)*K388+BU388+BY388+CB388*K388+CC388*K388)+CJ388+CK388*L388+CL388*L388+((CN388+CO388+CP388+CR388+CS388)*L388+CM388+CQ388+CT388*L388+CU388*L388)+IF(AND(M388>0,MAX(M388,N388/1000)<1),DB388+1*(DC388+DD388)+(1*(DF388+DG388+DH388+DJ388+DK388)+DE388+DI388+DL388+DM388),IF(AND(M388>0,MAX(M388,N388/1000)>1),DB388+MAX(M388,N388/1000)*(DC388+DD388)+(MAX(M388,N388/1000)*(DF388+DG388+DH388+DJ388+DK388)+DE388+DI388+DL388+DM388),IF(AND(K388="",L388="",M388=""),DB388+N388*(DC388+DD388)+((DF388+DG388+DH388+DJ388+DK388)*N388+DE388+DI388+DL388+DM388),0))) -> 0 | ED388: =AN388*K388*(1-AO388%)+BB388*L388*(1-BC388%)+BP388*IF(AND(M388>0,M388<1),1,IF(M388>1,MAX(M388,N388/1000),N388))*(1-BQ388%) -> 0 | EE388: =(CD388+CE388*K388)*(1-CF388%)+(CG388+CH388*K388)*(1-CI388%)+(CV388+CW388*L388)*(1-CX388%)+(CY388+CZ388*L388)*(1-DA388%)+(DN388+DO388*IF(AND(M388>0,M388<1),1,IF(M388>1,MAX(M388,N388/1000),N388)))*(1-DP388%)+(DQ388+DR388*IF(AND(M388>0,M388<1),1,IF(M388>1,MAX(M388,N388/1000),N388)))*(1-DS388%) -> 0 | EG388: =((BR388+BS388*K388+BT388*K388)+(CJ388+CK388*L388*+CL388*L388)+IF(AND(M388>0,MAX(M388,N388/1000)<1),DB388+DC388+DD388,IF(AND(M388>0,MAX(M388,N388/1000)>1),DB388+DC388*M388+DD388*M388,IF(AND(M388>0,MAX(M388,N388/1000)>1),DB388+MAX(M388,N388/1000)*DC388+MAX(M388,N388/1000)*DD388+IF(AND(K388="",L388="",M388=""),DB388+DC388*N388+DD388*N388,0)))))*EF388/365*ES388% -> 0 | EI388: =(((BV388+BW388+BX388+BZ388+CA388)*K388+BU388+BY388)*1.08+CJ388+CK388*L388+CL388*L388+((CN388+CO388+CP388+CR388+CS388)*L388+CM388+CQ388)*1.08+IF(AND(M388>0,MAX(M388,N388/1000)<1),DB388+1*(DC388+DD388)+(1*(DF388+DG388+DH388+DJ388+DK388)+DE388+DI388)*1.08,IF(AND(M388>0,MAX(M388,N388/1000)>1),DB388+MAX(M388,N388/1000)*(DC388+DD388)+(MAX(M388,N388/1000)*(DF388+DG388+DH388+DJ388+DK388)+DE388+DI388)*1.08,IF(AND(K388="",L388="",M388=""),DB388+N388*(DC388+DD388)+((DF388+DG388+DH388+DJ388+DK388)*N388+DE388+DI388)*1.08,0))))*EH388/365*ES388% -> 0 | EK388: =((CB388*K388+CC388*K388)*1.1+(CT388*L388+CU388*L388)*1.1+(DL388+DM388)*1.1)*EJ388/365*ES388% -> 0 | EQ388: =EC388-EB388-EG388-EI388-EK388-(AN388*K388+BB388*L388+BP388*IF(AND(M388>0,M388<1),1,IF(M388>1,MAX(M388,N388/1000),N388))+CD388+CE388*K388+CV388+CW388*L388+DN388+DO388*IF(AND(M388>0,M388<1),1,IF(M388>1,MAX(M388,N388/1000),N388))+CG388+CH388*K388+CY388+CZ388*L388+DQ388+DR388*IF(AND(M388>0,M388<1),1,IF(M388>1,MAX(M388,N388/1000),N388)))-EL388-EM388*EN388/365*ES388%-EO388*EP388/365*ES388% -> 0 | ER388: 23300 | ES388: 7.5
EB389: =AB389+AC389*K389+AD389*K389+((AF389+AG389+AH389+AJ389+AK389)*K389+AE389+AI389+AL389*K389+AM389*K389)+AP389+AQ389*L389+AR389*L389+((AT389+AU389+AV389+AX389+AY389)*L389+AS389+AW389+AZ389*L389+BA389*L389)+IF(AND(M389>0,MAX(M389,N389/1000)<1),BD389+1*(BE389+BF389)+(1*(BH389+BI389+BJ389+BL389+BM389)+BG389+BK389+BN389+BO389),IF(AND(M389>0,MAX(M389,N389/1000)>1),BD389+MAX(M389,N389/1000)*(BE389+BF389)+(MAX(M389,N389/1000)*(BH389+BI389+BJ389+BL389+BM389)+BG389+BK389+BN389+BO389),IF(AND(K389="",L389="",M389=""),BD389+N389*(BE389+BF389)+((BH389+BI389+BJ389+BL389+BM389)*N389+BG389+BK389+BN389+BO389),0))) -> 0 | EC389: =BR389+BS389*K389+BT389*K389+((BV389+BW389+BX389+BZ389+CA389)*K389+BU389+BY389+CB389*K389+CC389*K389)+CJ389+CK389*L389+CL389*L389+((CN389+CO389+CP389+CR389+CS389)*L389+CM389+CQ389+CT389*L389+CU389*L389)+IF(AND(M389>0,MAX(M389,N389/1000)<1),DB389+1*(DC389+DD389)+(1*(DF389+DG389+DH389+DJ389+DK389)+DE389+DI389+DL389+DM389),IF(AND(M389>0,MAX(M389,N389/1000)>1),DB389+MAX(M389,N389/1000)*(DC389+DD389)+(MAX(M389,N389/1000)*(DF389+DG389+DH389+DJ389+DK389)+DE389+DI389+DL389+DM389),IF(AND(K389="",L389="",M389=""),DB389+N389*(DC389+DD389)+((DF389+DG389+DH389+DJ389+DK389)*N389+DE389+DI389+DL389+DM389),0))) -> 0 | ED389: =AN389*K389*(1-AO389%)+BB389*L389*(1-BC389%)+BP389*IF(AND(M389>0,M389<1),1,IF(M389>1,MAX(M389,N389/1000),N389))*(1-BQ389%) -> 0 | EE389: =(CD389+CE389*K389)*(1-CF389%)+(CG389+CH389*K389)*(1-CI389%)+(CV389+CW389*L389)*(1-CX389%)+(CY389+CZ389*L389)*(1-DA389%)+(DN389+DO389*IF(AND(M389>0,M389<1),1,IF(M389>1,MAX(M389,N389/1000),N389)))*(1-DP389%)+(DQ389+DR389*IF(AND(M389>0,M389<1),1,IF(M389>1,MAX(M389,N389/1000),N389)))*(1-DS389%) -> 0 | EG389: =((BR389+BS389*K389+BT389*K389)+(CJ389+CK389*L389*+CL389*L389)+IF(AND(M389>0,MAX(M389,N389/1000)<1),DB389+DC389+DD389,IF(AND(M389>0,MAX(M389,N389/1000)>1),DB389+DC389*M389+DD389*M389,IF(AND(M389>0,MAX(M389,N389/1000)>1),DB389+MAX(M389,N389/1000)*DC389+MAX(M389,N389/1000)*DD389+IF(AND(K389="",L389="",M389=""),DB389+DC389*N389+DD389*N389,0)))))*EF389/365*ES389% -> 0 | EI389: =(((BV389+BW389+BX389+BZ389+CA389)*K389+BU389+BY389)*1.08+CJ389+CK389*L389+CL389*L389+((CN389+CO389+CP389+CR389+CS389)*L389+CM389+CQ389)*1.08+IF(AND(M389>0,MAX(M389,N389/1000)<1),DB389+1*(DC389+DD389)+(1*(DF389+DG389+DH389+DJ389+DK389)+DE389+DI389)*1.08,IF(AND(M389>0,MAX(M389,N389/1000)>1),DB389+MAX(M389,N389/1000)*(DC389+DD389)+(MAX(M389,N389/1000)*(DF389+DG389+DH389+DJ389+DK389)+DE389+DI389)*1.08,IF(AND(K389="",L389="",M389=""),DB389+N389*(DC389+DD389)+((DF389+DG389+DH389+DJ389+DK389)*N389+DE389+DI389)*1.08,0))))*EH389/365*ES389% -> 0 | EK389: =((CB389*K389+CC389*K389)*1.1+(CT389*L389+CU389*L389)*1.1+(DL389+DM389)*1.1)*EJ389/365*ES389% -> 0 | EQ389: =EC389-EB389-EG389-EI389-EK389-(AN389*K389+BB389*L389+BP389*IF(AND(M389>0,M389<1),1,IF(M389>1,MAX(M389,N389/1000),N389))+CD389+CE389*K389+CV389+CW389*L389+DN389+DO389*IF(AND(M389>0,M389<1),1,IF(M389>1,MAX(M389,N389/1000),N389))+CG389+CH389*K389+CY389+CZ389*L389+DQ389+DR389*IF(AND(M389>0,M389<1),1,IF(M389>1,MAX(M389,N389/1000),N389)))-EL389-EM389*EN389/365*ES389%-EO389*EP389/365*ES389% -> 0 | ER389: 23300 | ES389: 7.5
